Workbook

Sheet الصفحه الرئيسيه

Sheet دليل الحسابات
C14: م | D14: اسم الحساب
C15: 1 | D15: النقديه
C16: 2 | D16: البنك
C17: 3 | D17: المبيعات
C18: 4 | D18: المشتريات
C19: 5 | D19: العملاء
C20: 6 | D20: الموردون
C21: 7 | D21: جارى الشركاء
C22: 8 | D22: راس المال
C23: 9 | D23: المخزون
C24: 10 | D24: الايرادات
C25: 11 | D25: المصروفات
C26: 12 | D26: أرصده مدينة
... C29: 15 | D29: الضريبه المضافه

Sheet ارصده افتتاحيه
L8: =L32-M32 -> 0
A10: م | B10: التاريخ | C10: البيان | D10: نوع البيان | G10: متزن | H10: الفرق | J10: الاجمالى | L10: النقدية | N10: البنك | P10: المبيعات | R10: المشتريات | T10: العملاء | V10: الموردون | X10: جارى الشركات | Z10: رأس المال | AB10: المخزون | AD10: الايرادات | AF10: المصروفات | AH10: ارصده مدينة | AJ10: ارصده دائنة | AL10: ارصده دائنة | AN10: ارباح مرحله | AP10: القيمه المضافة
D11: صرف | E11: التحصيل | F11: اثبات | J11: مدين | K11: دائن | L11: مدين | M11: دائن | N11: مدين | O11: دائن | P11: مدين | Q11: دائن | R11: مدين | S11: دائن | T11: مدين | U11: دائن | V11: مدين | W11: دائن | X11: مدين | Y11: دائن | Z11: مدين | AA11: دائن | AB11: مدين | AC11: دائن | AD11: مدين | AE11: دائن | AF11: مدين | AG11: دائن | AH11: مدين | AI11: دائن | AJ11: مدين | AK11: دائن | AL11: مدين | AM11: دائن | AN11: مدين | AO11: دائن | AP11: مدين | AQ11: دائن
A12: 1 | G12: =IF(J12>K12,"متزن",IF(J12<K12,"غير متزن","")) | H12: =IF(J12>K12,"ذياده",IF(J12<K12,"ناقص","")) | I12: =IF(J12>K12,J12-K12,K12-J12) -> 0 | J12: =SUMIF($L$11:$AQ$11,$L$11,L12:AQ12) -> 0 | K12: =SUMIF($L$11:$AQ$11,$M$11,L12:AQ12) -> 0
A13: 2 | G13: =IF(J13>K13,"متزن",IF(J13<K13,"غير متزن","")) | H13: =IF(J13>K13,"ذياده",IF(J13<K13,"ناقص","")) | I13: =IF(J13>K13,J13-K13,K13-J13) -> 0 | J13: =SUMIF($L$11:$AQ$11,$L$11,L13:AQ13) -> 0 | K13: =SUMIF($L$11:$AQ$11,$M$11,L13:AQ13) -> 0
A14: 3 | G14: =IF(J14>K14,"متزن",IF(J14<K14,"غير متزن","")) | H14: =IF(J14>K14,"ذياده",IF(J14<K14,"ناقص","")) | I14: =IF(J14>K14,J14-K14,K14-J14) -> 0 | J14: =SUMIF($L$11:$AQ$11,$L$11,L14:AQ14) -> 0 | K14: =SUMIF($L$11:$AQ$11,$M$11,L14:AQ14) -> 0
A15: 4 | G15: =IF(J15>K15,"متزن",IF(J15<K15,"غير متزن","")) | H15: =IF(J15>K15,"ذياده",IF(J15<K15,"ناقص","")) | I15: =IF(J15>K15,J15-K15,K15-J15) -> 0 | J15: =SUMIF($L$11:$AQ$11,$L$11,L15:AQ15) -> 0 | K15: =SUMIF($L$11:$AQ$11,$M$11,L15:AQ15) -> 0
A16: 5 | G16: =IF(J16>K16,"متزن",IF(J16<K16,"غير متزن","")) | H16: =IF(J16>K16,"ذياده",IF(J16<K16,"ناقص","")) | I16: =IF(J16>K16,J16-K16,K16-J16) -> 0 | J16: =SUMIF($L$11:$AQ$11,$L$11,L16:AQ16) -> 0 | K16: =SUMIF($L$11:$AQ$11,$M$11,L16:AQ16) -> 0
A17: 6 | G17: =IF(J17>K17,"متزن",IF(J17<K17,"غير متزن","")) | H17: =IF(J17>K17,"ذياده",IF(J17<K17,"ناقص","")) | I17: =IF(J17>K17,J17-K17,K17-J17) -> 0 | J17: =SUMIF($L$11:$AQ$11,$L$11,L17:AQ17) -> 0 | K17: =SUMIF($L$11:$AQ$11,$M$11,L17:AQ17) -> 0
A18: 7 | G18: =IF(J18>K18,"متزن",IF(J18<K18,"غير متزن","")) | H18: =IF(J18>K18,"ذياده",IF(J18<K18,"ناقص","")) | I18: =IF(J18>K18,J18-K18,K18-J18) -> 0 | J18: =SUMIF($L$11:$AQ$11,$L$11,L18:AQ18) -> 0 | K18: =SUMIF($L$11:$AQ$11,$M$11,L18:AQ18) -> 0
A19: 8 | G19: =IF(J19>K19,"متزن",IF(J19<K19,"غير متزن","")) | H19: =IF(J19>K19,"ذياده",IF(J19<K19,"ناقص","")) | I19: =IF(J19>K19,J19-K19,K19-J19) -> 0 | J19: =SUMIF($L$11:$AQ$11,$L$11,L19:AQ19) -> 0 | K19: =SUMIF($L$11:$AQ$11,$M$11,L19:AQ19) -> 0
A20: 9 | G20: =IF(J20>K20,"متزن",IF(J20<K20,"غير متزن","")) | H20: =IF(J20>K20,"ذياده",IF(J20<K20,"ناقص","")) | I20: =IF(J20>K20,J20-K20,K20-J20) -> 0 | J20: =SUMIF($L$11:$AQ$11,$L$11,L20:AQ20) -> 0 | K20: =SUMIF($L$11:$AQ$11,$M$11,L20:AQ20) -> 0
A21: 10 | G21: =IF(J21>K21,"متزن",IF(J21<K21,"غير متزن","")) | H21: =IF(J21>K21,"ذياده",IF(J21<K21,"ناقص","")) | I21: =IF(J21>K21,J21-K21,K21-J21) -> 0 | J21: =SUMIF($L$11:$AQ$11,$L$11,L21:AQ21) -> 0 | K21: =SUMIF($L$11:$AQ$11,$M$11,L21:AQ21) -> 0
A22: 11 | G22: =IF(J22>K22,"متزن",IF(J22<K22,"غير متزن","")) | H22: =IF(J22>K22,"ذياده",IF(J22<K22,"ناقص","")) | I22: =IF(J22>K22,J22-K22,K22-J22) -> 0 | J22: =SUMIF($L$11:$AQ$11,$L$11,L22:AQ22) -> 0 | K22: =SUMIF($L$11:$AQ$11,$M$11,L22:AQ22) -> 0
A23: 12 | G23: =IF(J23>K23,"متزن",IF(J23<K23,"غير متزن","")) | H23: =IF(J23>K23,"ذياده",IF(J23<K23,"ناقص","")) | I23: =IF(J23>K23,J23-K23,K23-J23) -> 0 | J23: =SUMIF($L$11:$AQ$11,$L$11,L23:AQ23) -> 0 | K23: =SUMIF($L$11:$AQ$11,$M$11,L23:AQ23) -> 0
... A31: 20 | G31: =IF(J31>K31,"متزن",IF(J31<K31,"غير متزن","")) | H31: =IF(J31>K31,"ذياده",IF(J31<K31,"ناقص","")) | I31: =IF(J31>K31,J31-K31,K31-J31) -> 0 | J31: =SUMIF($L$11:$AQ$11,$L$11,L31:AQ31) -> 0 | K31: =SUMIF($L$11:$AQ$11,$M$11,L31:AQ31) -> 0
A32: الاجمالى | H32: =IF(J32>K32,"ذياده",IF(J32<K32,"ناقص","")) | J32: =SUM(J12:J31) -> 0 | K32: =SUM(K12:K31) -> 0 | L32: =SUM(L12:L31) -> 0 | M32: =SUM(M12:M31) -> 0 | N32: =SUM(N12:N31) -> 0 | O32: =SUM(O12:O31) -> 0 | P32: =SUM(P12:P31) -> 0 | Q32: =SUM(Q12:Q31) -> 0 | ... AQ32: =SUM(AQ12:AQ31) -> 0

Sheet 1
L8: =L32-M32+SUM('ارصده افتتاحيه'!L8:M8) -> 0 | N8: =N32-O32+SUM('ارصده افتتاحيه'!N8:O8) -> 0 | P8: =P32-Q32+SUM('ارصده افتتاحيه'!P8:Q8) -> 0 | R8: =R32-S32+SUM('ارصده افتتاحيه'!R8:S8) -> 0 | T8: =T32-U32+SUM('ارصده افتتاحيه'!T8:U8) -> 0 | V8: =V32-W32+SUM('ارصده افتتاحيه'!V8:W8) -> 0 | X8: =X32-Y32+SUM('ارصده افتتاحيه'!X8:Y8) -> 0 | Z8: =Z32-AA32+SUM('ارصده افتتاحيه'!Z8:AA8) -> 0 | AB8: =AB32-AC32+SUM('ارصده افتتاحيه'!AB8:AC8) -> 0 | AD8: =AD32-AE32+SUM('ارصده افتتاحيه'!AD8:AE8) -> 0 | AF8: =AF32-AG32+SUM('ارصده افتتاحيه'!AF8:AG8) -> 0 | AH8: =AH32-AI32+SUM('ارصده افتتاحيه'!AH8:AI8) -> 0 | AJ8: =AJ32-AK32+SUM('ارصده افتتاحيه'!AJ8:AK8) -> 0 | AL8: =AL32-AM32+SUM('ارصده افتتاحيه'!AL8:AM8) -> 0 | AN8: =AN32-AO32+SUM('ارصده افتتاحيه'!AN8:AO8) -> 0 | AP8: =AP32-AQ32+SUM('ارصده افتتاحيه'!AP8:AQ8) -> 0
A10: م | B10: التاريخ | C10: البيان | D10: نوع البيان | G10: متزن | H10: الفرق | J10: الاجمالى | L10: النقدية | N10: البنك | P10: المبيعات | R10: المشتريات | T10: العملاء | V10: الموردون | X10: جارى الشركات | Z10: رأس المال | AB10: المخزون | AD10: الايرادات | AF10: المصروفات | AH10: ارصده مدينة | AJ10: ارصده دائنة | AL10: ارصده دائنة | AN10: ارباح مرحله | AP10: القيمه المضافة
D11: صرف | E11: التحصيل | F11: اثبات | J11: مدين | K11: دائن | L11: مدين | M11: دائن | N11: مدين | O11: دائن | P11: مدين | Q11: دائن | R11: مدين | S11: دائن | T11: مدين | U11: دائن | V11: مدين | W11: دائن | X11: مدين | Y11: دائن | Z11: مدين | AA11: دائن | AB11: مدين | AC11: دائن | AD11: مدين | AE11: دائن | AF11: مدين | AG11: دائن | AH11: مدين | AI11: دائن | AJ11: مدين | AK11: دائن | AL11: مدين | AM11: دائن | AN11: مدين | AO11: دائن | AP11: مدين | AQ11: دائن
A12: 1 | G12: =IF(J12>K12,"متزن",IF(J12<K12,"غير متزن","")) | H12: =IF(J12>K12,"ذياده",IF(J12<K12,"ناقص","")) | I12: =IF(J12>K12,J12-K12,K12-J12) -> 0 | J12: =SUMIF($L$11:$AQ$11,$L$11,L12:AQ12) -> 0 | K12: =SUMIF($L$11:$AQ$11,$M$11,L12:AQ12) -> 0
A13: 2 | G13: =IF(J13>K13,"متزن",IF(J13<K13,"غير متزن","")) | H13: =IF(J13>K13,"ذياده",IF(J13<K13,"ناقص","")) | I13: =IF(J13>K13,J13-K13,K13-J13) -> 0 | J13: =SUMIF($L$11:$AQ$11,$L$11,L13:AQ13) -> 0 | K13: =SUMIF($L$11:$AQ$11,$M$11,L13:AQ13) -> 0
A14: 3 | G14: =IF(J14>K14,"متزن",IF(J14<K14,"غير متزن","")) | H14: =IF(J14>K14,"ذياده",IF(J14<K14,"ناقص","")) | I14: =IF(J14>K14,J14-K14,K14-J14) -> 0 | J14: =SUMIF($L$11:$AQ$11,$L$11,L14:AQ14) -> 0 | K14: =SUMIF($L$11:$AQ$11,$M$11,L14:AQ14) -> 0
A15: 4 | G15: =IF(J15>K15,"متزن",IF(J15<K15,"غير متزن","")) | H15: =IF(J15>K15,"ذياده",IF(J15<K15,"ناقص","")) | I15: =IF(J15>K15,J15-K15,K15-J15) -> 0 | J15: =SUMIF($L$11:$AQ$11,$L$11,L15:AQ15) -> 0 | K15: =SUMIF($L$11:$AQ$11,$M$11,L15:AQ15) -> 0
A16: 5 | G16: =IF(J16>K16,"متزن",IF(J16<K16,"غير متزن","")) | H16: =IF(J16>K16,"ذياده",IF(J16<K16,"ناقص","")) | I16: =IF(J16>K16,J16-K16,K16-J16) -> 0 | J16: =SUMIF($L$11:$AQ$11,$L$11,L16:AQ16) -> 0 | K16: =SUMIF($L$11:$AQ$11,$M$11,L16:AQ16) -> 0
A17: 6 | G17: =IF(J17>K17,"متزن",IF(J17<K17,"غير متزن","")) | H17: =IF(J17>K17,"ذياده",IF(J17<K17,"ناقص","")) | I17: =IF(J17>K17,J17-K17,K17-J17) -> 0 | J17: =SUMIF($L$11:$AQ$11,$L$11,L17:AQ17) -> 0 | K17: =SUMIF($L$11:$AQ$11,$M$11,L17:AQ17) -> 0
A18: 7 | G18: =IF(J18>K18,"متزن",IF(J18<K18,"غير متزن","")) | H18: =IF(J18>K18,"ذياده",IF(J18<K18,"ناقص","")) | I18: =IF(J18>K18,J18-K18,K18-J18) -> 0 | J18: =SUMIF($L$11:$AQ$11,$L$11,L18:AQ18) -> 0 | K18: =SUMIF($L$11:$AQ$11,$M$11,L18:AQ18) -> 0
A19: 8 | G19: =IF(J19>K19,"متزن",IF(J19<K19,"غير متزن","")) | H19: =IF(J19>K19,"ذياده",IF(J19<K19,"ناقص","")) | I19: =IF(J19>K19,J19-K19,K19-J19) -> 0 | J19: =SUMIF($L$11:$AQ$11,$L$11,L19:AQ19) -> 0 | K19: =SUMIF($L$11:$AQ$11,$M$11,L19:AQ19) -> 0
A20: 9 | G20: =IF(J20>K20,"متزن",IF(J20<K20,"غير متزن","")) | H20: =IF(J20>K20,"ذياده",IF(J20<K20,"ناقص","")) | I20: =IF(J20>K20,J20-K20,K20-J20) -> 0 | J20: =SUMIF($L$11:$AQ$11,$L$11,L20:AQ20) -> 0 | K20: =SUMIF($L$11:$AQ$11,$M$11,L20:AQ20) -> 0
A21: 10 | G21: =IF(J21>K21,"متزن",IF(J21<K21,"غير متزن","")) | H21: =IF(J21>K21,"ذياده",IF(J21<K21,"ناقص","")) | I21: =IF(J21>K21,J21-K21,K21-J21) -> 0 | J21: =SUMIF($L$11:$AQ$11,$L$11,L21:AQ21) -> 0 | K21: =SUMIF($L$11:$AQ$11,$M$11,L21:AQ21) -> 0
A22: 11 | G22: =IF(J22>K22,"متزن",IF(J22<K22,"غير متزن","")) | H22: =IF(J22>K22,"ذياده",IF(J22<K22,"ناقص","")) | I22: =IF(J22>K22,J22-K22,K22-J22) -> 0 | J22: =SUMIF($L$11:$AQ$11,$L$11,L22:AQ22) -> 0 | K22: =SUMIF($L$11:$AQ$11,$M$11,L22:AQ22) -> 0
A23: 12 | G23: =IF(J23>K23,"متزن",IF(J23<K23,"غير متزن","")) | H23: =IF(J23>K23,"ذياده",IF(J23<K23,"ناقص","")) | I23: =IF(J23>K23,J23-K23,K23-J23) -> 0 | J23: =SUMIF($L$11:$AQ$11,$L$11,L23:AQ23) -> 0 | K23: =SUMIF($L$11:$AQ$11,$M$11,L23:AQ23) -> 0
... A31: 20 | G31: =IF(J31>K31,"متزن",IF(J31<K31,"غير متزن","")) | H31: =IF(J31>K31,"ذياده",IF(J31<K31,"ناقص","")) | I31: =IF(J31>K31,J31-K31,K31-J31) -> 0 | J31: =SUMIF($L$11:$AQ$11,$L$11,L31:AQ31) -> 0 | K31: =SUMIF($L$11:$AQ$11,$M$11,L31:AQ31) -> 0
A32: الاجمالى | H32: =IF(J32>K32,"ذياده",IF(J32<K32,"ناقص","")) | J32: =SUM(J12:J31) -> 0 | K32: =SUM(K12:K31) -> 0 | L32: =SUM(L12:L31) -> 0 | M32: =SUM(M12:M31) -> 0 | N32: =SUM(N12:N31) -> 0 | O32: =SUM(O12:O31) -> 0 | P32: =SUM(P12:P31) -> 0 | Q32: =SUM(Q12:Q31) -> 0 | ... AQ32: =SUM(AQ12:AQ31) -> 0

Sheet 2
L8: =L32-M32+SUM('1'!L8:M8) -> 0 | N8: =N32-O32+SUM('1'!N8:O8) -> 0 | P8: =P32-Q32+SUM('1'!P8:Q8) -> 0 | R8: =R32-S32+SUM('1'!R8:S8) -> 0 | T8: =T32-U32+SUM('1'!T8:U8) -> 0 | V8: =V32-W32+SUM('1'!V8:W8) -> 0 | X8: =X32-Y32+SUM('1'!X8:Y8) -> 0 | Z8: =Z32-AA32+SUM('1'!Z8:AA8) -> 0 | AB8: =AB32-AC32+SUM('1'!AB8:AC8) -> 0 | AD8: =AD32-AE32+SUM('1'!AD8:AE8) -> 0 | AF8: =AF32-AG32+SUM('1'!AF8:AG8) -> 0 | AH8: =AH32-AI32+SUM('1'!AH8:AI8) -> 0 | AJ8: =AJ32-AK32+SUM('1'!AJ8:AK8) -> 0 | AL8: =AL32-AM32+SUM('1'!AL8:AM8) -> 0 | AN8: =AN32-AO32+SUM('1'!AN8:AO8) -> 0 | AP8: =AP32-AQ32+SUM('1'!AP8:AQ8) -> 0
A10: م | B10: التاريخ | C10: البيان | D10: نوع البيان | G10: متزن | H10: الفرق | J10: الاجمالى | L10: النقدية | N10: البنك | P10: المبيعات | R10: المشتريات | T10: العملاء | V10: الموردون | X10: جارى الشركات | Z10: رأس المال | AB10: المخزون | AD10: الايرادات | AF10: المصروفات | AH10: ارصده مدينة | AJ10: ارصده دائنة | AL10: ارصده دائنة | AN10: ارباح مرحله | AP10: القيمه المضافة
D11: صرف | E11: التحصيل | F11: اثبات | J11: مدين | K11: دائن | L11: مدين | M11: دائن | N11: مدين | O11: دائن | P11: مدين | Q11: دائن | R11: مدين | S11: دائن | T11: مدين | U11: دائن | V11: مدين | W11: دائن | X11: مدين | Y11: دائن | Z11: مدين | AA11: دائن | AB11: مدين | AC11: دائن | AD11: مدين | AE11: دائن | AF11: مدين | AG11: دائن | AH11: مدين | AI11: دائن | AJ11: مدين | AK11: دائن | AL11: مدين | AM11: دائن | AN11: مدين | AO11: دائن | AP11: مدين | AQ11: دائن
A12: 1 | G12: =IF(J12>K12,"متزن",IF(J12<K12,"غير متزن","")) | H12: =IF(J12>K12,"ذياده",IF(J12<K12,"ناقص","")) | I12: =IF(J12>K12,J12-K12,K12-J12) -> 0 | J12: =SUMIF($L$11:$AQ$11,$L$11,L12:AQ12) -> 0 | K12: =SUMIF($L$11:$AQ$11,$M$11,L12:AQ12) -> 0
A13: 2 | G13: =IF(J13>K13,"متزن",IF(J13<K13,"غير متزن","")) | H13: =IF(J13>K13,"ذياده",IF(J13<K13,"ناقص","")) | I13: =IF(J13>K13,J13-K13,K13-J13) -> 0 | J13: =SUMIF($L$11:$AQ$11,$L$11,L13:AQ13) -> 0 | K13: =SUMIF($L$11:$AQ$11,$M$11,L13:AQ13) -> 0
A14: 3 | G14: =IF(J14>K14,"متزن",IF(J14<K14,"غير متزن","")) | H14: =IF(J14>K14,"ذياده",IF(J14<K14,"ناقص","")) | I14: =IF(J14>K14,J14-K14,K14-J14) -> 0 | J14: =SUMIF($L$11:$AQ$11,$L$11,L14:AQ14) -> 0 | K14: =SUMIF($L$11:$AQ$11,$M$11,L14:AQ14) -> 0
A15: 4 | G15: =IF(J15>K15,"متزن",IF(J15<K15,"غير متزن","")) | H15: =IF(J15>K15,"ذياده",IF(J15<K15,"ناقص","")) | I15: =IF(J15>K15,J15-K15,K15-J15) -> 0 | J15: =SUMIF($L$11:$AQ$11,$L$11,L15:AQ15) -> 0 | K15: =SUMIF($L$11:$AQ$11,$M$11,L15:AQ15) -> 0
A16: 5 | G16: =IF(J16>K16,"متزن",IF(J16<K16,"غير متزن","")) | H16: =IF(J16>K16,"ذياده",IF(J16<K16,"ناقص","")) | I16: =IF(J16>K16,J16-K16,K16-J16) -> 0 | J16: =SUMIF($L$11:$AQ$11,$L$11,L16:AQ16) -> 0 | K16: =SUMIF($L$11:$AQ$11,$M$11,L16:AQ16) -> 0
A17: 6 | G17: =IF(J17>K17,"متزن",IF(J17<K17,"غير متزن","")) | H17: =IF(J17>K17,"ذياده",IF(J17<K17,"ناقص","")) | I17: =IF(J17>K17,J17-K17,K17-J17) -> 0 | J17: =SUMIF($L$11:$AQ$11,$L$11,L17:AQ17) -> 0 | K17: =SUMIF($L$11:$AQ$11,$M$11,L17:AQ17) -> 0
A18: 7 | G18: =IF(J18>K18,"متزن",IF(J18<K18,"غير متزن","")) | H18: =IF(J18>K18,"ذياده",IF(J18<K18,"ناقص","")) | I18: =IF(J18>K18,J18-K18,K18-J18) -> 0 | J18: =SUMIF($L$11:$AQ$11,$L$11,L18:AQ18) -> 0 | K18: =SUMIF($L$11:$AQ$11,$M$11,L18:AQ18) -> 0
A19: 8 | G19: =IF(J19>K19,"متزن",IF(J19<K19,"غير متزن","")) | H19: =IF(J19>K19,"ذياده",IF(J19<K19,"ناقص","")) | I19: =IF(J19>K19,J19-K19,K19-J19) -> 0 | J19: =SUMIF($L$11:$AQ$11,$L$11,L19:AQ19) -> 0 | K19: =SUMIF($L$11:$AQ$11,$M$11,L19:AQ19) -> 0
A20: 9 | G20: =IF(J20>K20,"متزن",IF(J20<K20,"غير متزن","")) | H20: =IF(J20>K20,"ذياده",IF(J20<K20,"ناقص","")) | I20: =IF(J20>K20,J20-K20,K20-J20) -> 0 | J20: =SUMIF($L$11:$AQ$11,$L$11,L20:AQ20) -> 0 | K20: =SUMIF($L$11:$AQ$11,$M$11,L20:AQ20) -> 0
A21: 10 | G21: =IF(J21>K21,"متزن",IF(J21<K21,"غير متزن","")) | H21: =IF(J21>K21,"ذياده",IF(J21<K21,"ناقص","")) | I21: =IF(J21>K21,J21-K21,K21-J21) -> 0 | J21: =SUMIF($L$11:$AQ$11,$L$11,L21:AQ21) -> 0 | K21: =SUMIF($L$11:$AQ$11,$M$11,L21:AQ21) -> 0
A22: 11 | G22: =IF(J22>K22,"متزن",IF(J22<K22,"غير متزن","")) | H22: =IF(J22>K22,"ذياده",IF(J22<K22,"ناقص","")) | I22: =IF(J22>K22,J22-K22,K22-J22) -> 0 | J22: =SUMIF($L$11:$AQ$11,$L$11,L22:AQ22) -> 0 | K22: =SUMIF($L$11:$AQ$11,$M$11,L22:AQ22) -> 0
A23: 12 | G23: =IF(J23>K23,"متزن",IF(J23<K23,"غير متزن","")) | H23: =IF(J23>K23,"ذياده",IF(J23<K23,"ناقص","")) | I23: =IF(J23>K23,J23-K23,K23-J23) -> 0 | J23: =SUMIF($L$11:$AQ$11,$L$11,L23:AQ23) -> 0 | K23: =SUMIF($L$11:$AQ$11,$M$11,L23:AQ23) -> 0
... A31: 20 | G31: =IF(J31>K31,"متزن",IF(J31<K31,"غير متزن","")) | H31: =IF(J31>K31,"ذياده",IF(J31<K31,"ناقص","")) | I31: =IF(J31>K31,J31-K31,K31-J31) -> 0 | J31: =SUMIF($L$11:$AQ$11,$L$11,L31:AQ31) -> 0 | K31: =SUMIF($L$11:$AQ$11,$M$11,L31:AQ31) -> 0
A32: الاجمالى | H32: =IF(J32>K32,"ذياده",IF(J32<K32,"ناقص","")) | J32: =SUM(J12:J31) -> 0 | K32: =SUM(K12:K31) -> 0 | L32: =SUM(L12:L31) -> 0 | M32: =SUM(M12:M31) -> 0 | N32: =SUM(N12:N31) -> 0 | O32: =SUM(O12:O31) -> 0 | P32: =SUM(P12:P31) -> 0 | Q32: =SUM(Q12:Q31) -> 0 | ... AQ32: =SUM(AQ12:AQ31) -> 0

Sheet 3
L8: =L32-M32+SUM('2'!L8:M8) -> 0 | N8: =N32-O32+SUM('2'!N8:O8) -> 0 | P8: =P32-Q32+SUM('2'!P8:Q8) -> 0 | R8: =R32-S32+SUM('2'!R8:S8) -> 0 | T8: =T32-U32+SUM('2'!T8:U8) -> 0 | V8: =V32-W32+SUM('2'!V8:W8) -> 0 | X8: =X32-Y32+SUM('2'!X8:Y8) -> 0 | Z8: =Z32-AA32+SUM('2'!Z8:AA8) -> 0 | AB8: =AB32-AC32+SUM('2'!AB8:AC8) -> 0 | AD8: =AD32-AE32+SUM('2'!AD8:AE8) -> 0 | AF8: =AF32-AG32+SUM('2'!AF8:AG8) -> 0 | AH8: =AH32-AI32+SUM('2'!AH8:AI8) -> 0 | AJ8: =AJ32-AK32+SUM('2'!AJ8:AK8) -> 0 | AL8: =AL32-AM32+SUM('2'!AL8:AM8) -> 0 | AN8: =AN32-AO32+SUM('2'!AN8:AO8) -> 0 | AP8: =AP32-AQ32+SUM('2'!AP8:AQ8) -> 0
A10: م | B10: التاريخ | C10: البيان | D10: نوع البيان | G10: متزن | H10: الفرق | J10: الاجمالى | L10: النقدية | N10: البنك | P10: المبيعات | R10: المشتريات | T10: العملاء | V10: الموردون | X10: جارى الشركات | Z10: رأس المال | AB10: المخزون | AD10: الايرادات | AF10: المصروفات | AH10: ارصده مدينة | AJ10: ارصده دائنة | AL10: ارصده دائنة | AN10: ارباح مرحله | AP10: القيمه المضافة
D11: صرف | E11: التحصيل | F11: اثبات | J11: مدين | K11: دائن | L11: مدين | M11: دائن | N11: مدين | O11: دائن | P11: مدين | Q11: دائن | R11: مدين | S11: دائن | T11: مدين | U11: دائن | V11: مدين | W11: دائن | X11: مدين | Y11: دائن | Z11: مدين | AA11: دائن | AB11: مدين | AC11: دائن | AD11: مدين | AE11: دائن | AF11: مدين | AG11: دائن | AH11: مدين | AI11: دائن | AJ11: مدين | AK11: دائن | AL11: مدين | AM11: دائن | AN11: مدين | AO11: دائن | AP11: مدين | AQ11: دائن
A12: 1 | G12: =IF(J12>K12,"متزن",IF(J12<K12,"غير متزن","")) | H12: =IF(J12>K12,"ذياده",IF(J12<K12,"ناقص","")) | I12: =IF(J12>K12,J12-K12,K12-J12) -> 0 | J12: =SUMIF($L$11:$AQ$11,$L$11,L12:AQ12) -> 0 | K12: =SUMIF($L$11:$AQ$11,$M$11,L12:AQ12) -> 0
A13: 2 | G13: =IF(J13>K13,"متزن",IF(J13<K13,"غير متزن","")) | H13: =IF(J13>K13,"ذياده",IF(J13<K13,"ناقص","")) | I13: =IF(J13>K13,J13-K13,K13-J13) -> 0 | J13: =SUMIF($L$11:$AQ$11,$L$11,L13:AQ13) -> 0 | K13: =SUMIF($L$11:$AQ$11,$M$11,L13:AQ13) -> 0
A14: 3 | G14: =IF(J14>K14,"متزن",IF(J14<K14,"غير متزن","")) | H14: =IF(J14>K14,"ذياده",IF(J14<K14,"ناقص","")) | I14: =IF(J14>K14,J14-K14,K14-J14) -> 0 | J14: =SUMIF($L$11:$AQ$11,$L$11,L14:AQ14) -> 0 | K14: =SUMIF($L$11:$AQ$11,$M$11,L14:AQ14) -> 0
A15: 4 | G15: =IF(J15>K15,"متزن",IF(J15<K15,"غير متزن","")) | H15: =IF(J15>K15,"ذياده",IF(J15<K15,"ناقص","")) | I15: =IF(J15>K15,J15-K15,K15-J15) -> 0 | J15: =SUMIF($L$11:$AQ$11,$L$11,L15:AQ15) -> 0 | K15: =SUMIF($L$11:$AQ$11,$M$11,L15:AQ15) -> 0
A16: 5 | G16: =IF(J16>K16,"متزن",IF(J16<K16,"غير متزن","")) | H16: =IF(J16>K16,"ذياده",IF(J16<K16,"ناقص","")) | I16: =IF(J16>K16,J16-K16,K16-J16) -> 0 | J16: =SUMIF($L$11:$AQ$11,$L$11,L16:AQ16) -> 0 | K16: =SUMIF($L$11:$AQ$11,$M$11,L16:AQ16) -> 0
A17: 6 | G17: =IF(J17>K17,"متزن",IF(J17<K17,"غير متزن","")) | H17: =IF(J17>K17,"ذياده",IF(J17<K17,"ناقص","")) | I17: =IF(J17>K17,J17-K17,K17-J17) -> 0 | J17: =SUMIF($L$11:$AQ$11,$L$11,L17:AQ17) -> 0 | K17: =SUMIF($L$11:$AQ$11,$M$11,L17:AQ17) -> 0
A18: 7 | G18: =IF(J18>K18,"متزن",IF(J18<K18,"غير متزن","")) | H18: =IF(J18>K18,"ذياده",IF(J18<K18,"ناقص","")) | I18: =IF(J18>K18,J18-K18,K18-J18) -> 0 | J18: =SUMIF($L$11:$AQ$11,$L$11,L18:AQ18) -> 0 | K18: =SUMIF($L$11:$AQ$11,$M$11,L18:AQ18) -> 0
A19: 8 | G19: =IF(J19>K19,"متزن",IF(J19<K19,"غير متزن","")) | H19: =IF(J19>K19,"ذياده",IF(J19<K19,"ناقص","")) | I19: =IF(J19>K19,J19-K19,K19-J19) -> 0 | J19: =SUMIF($L$11:$AQ$11,$L$11,L19:AQ19) -> 0 | K19: =SUMIF($L$11:$AQ$11,$M$11,L19:AQ19) -> 0
A20: 9 | G20: =IF(J20>K20,"متزن",IF(J20<K20,"غير متزن","")) | H20: =IF(J20>K20,"ذياده",IF(J20<K20,"ناقص","")) | I20: =IF(J20>K20,J20-K20,K20-J20) -> 0 | J20: =SUMIF($L$11:$AQ$11,$L$11,L20:AQ20) -> 0 | K20: =SUMIF($L$11:$AQ$11,$M$11,L20:AQ20) -> 0
A21: 10 | G21: =IF(J21>K21,"متزن",IF(J21<K21,"غير متزن","")) | H21: =IF(J21>K21,"ذياده",IF(J21<K21,"ناقص","")) | I21: =IF(J21>K21,J21-K21,K21-J21) -> 0 | J21: =SUMIF($L$11:$AQ$11,$L$11,L21:AQ21) -> 0 | K21: =SUMIF($L$11:$AQ$11,$M$11,L21:AQ21) -> 0
A22: 11 | G22: =IF(J22>K22,"متزن",IF(J22<K22,"غير متزن","")) | H22: =IF(J22>K22,"ذياده",IF(J22<K22,"ناقص","")) | I22: =IF(J22>K22,J22-K22,K22-J22) -> 0 | J22: =SUMIF($L$11:$AQ$11,$L$11,L22:AQ22) -> 0 | K22: =SUMIF($L$11:$AQ$11,$M$11,L22:AQ22) -> 0
A23: 12 | G23: =IF(J23>K23,"متزن",IF(J23<K23,"غير متزن","")) | H23: =IF(J23>K23,"ذياده",IF(J23<K23,"ناقص","")) | I23: =IF(J23>K23,J23-K23,K23-J23) -> 0 | J23: =SUMIF($L$11:$AQ$11,$L$11,L23:AQ23) -> 0 | K23: =SUMIF($L$11:$AQ$11,$M$11,L23:AQ23) -> 0
... A31: 20 | G31: =IF(J31>K31,"متزن",IF(J31<K31,"غير متزن","")) | H31: =IF(J31>K31,"ذياده",IF(J31<K31,"ناقص","")) | I31: =IF(J31>K31,J31-K31,K31-J31) -> 0 | J31: =SUMIF($L$11:$AQ$11,$L$11,L31:AQ31) -> 0 | K31: =SUMIF($L$11:$AQ$11,$M$11,L31:AQ31) -> 0
A32: الاجمالى | H32: =IF(J32>K32,"ذياده",IF(J32<K32,"ناقص","")) | J32: =SUM(J12:J31) -> 0 | K32: =SUM(K12:K31) -> 0 | L32: =SUM(L12:L31) -> 0 | M32: =SUM(M12:M31) -> 0 | N32: =SUM(N12:N31) -> 0 | O32: =SUM(O12:O31) -> 0 | P32: =SUM(P12:P31) -> 0 | Q32: =SUM(Q12:Q31) -> 0 | ... AQ32: =SUM(AQ12:AQ31) -> 0

Sheet 4
L8: =L32-M32+SUM('3'!L8:M8) -> 0 | N8: =N32-O32+SUM('3'!N8:O8) -> 0 | P8: =P32-Q32+SUM('3'!P8:Q8) -> 0 | R8: =R32-S32+SUM('3'!R8:S8) -> 0 | T8: =T32-U32+SUM('3'!T8:U8) -> 0 | V8: =V32-W32+SUM('3'!V8:W8) -> 0 | X8: =X32-Y32+SUM('3'!X8:Y8) -> 0 | Z8: =Z32-AA32+SUM('3'!Z8:AA8) -> 0 | AB8: =AB32-AC32+SUM('3'!AB8:AC8) -> 0 | AD8: =AD32-AE32+SUM('3'!AD8:AE8) -> 0 | AF8: =AF32-AG32+SUM('3'!AF8:AG8) -> 0 | AH8: =AH32-AI32+SUM('3'!AH8:AI8) -> 0 | AJ8: =AJ32-AK32+SUM('3'!AJ8:AK8) -> 0 | AL8: =AL32-AM32+SUM('3'!AL8:AM8) -> 0 | AN8: =AN32-AO32+SUM('3'!AN8:AO8) -> 0 | AP8: =AP32-AQ32+SUM('3'!AP8:AQ8) -> 0
A10: م | B10: التاريخ | C10: البيان | D10: نوع البيان | G10: متزن | H10: الفرق | J10: الاجمالى | L10: النقدية | N10: البنك | P10: المبيعات | R10: المشتريات | T10: العملاء | V10: الموردون | X10: جارى الشركات | Z10: رأس المال | AB10: المخزون | AD10: الايرادات | AF10: المصروفات | AH10: ارصده مدينة | AJ10: ارصده دائنة | AL10: ارصده دائنة | AN10: ارباح مرحله | AP10: القيمه المضافة
D11: صرف | E11: التحصيل | F11: اثبات | J11: مدين | K11: دائن | L11: مدين | M11: دائن | N11: مدين | O11: دائن | P11: مدين | Q11: دائن | R11: مدين | S11: دائن | T11: مدين | U11: دائن | V11: مدين | W11: دائن | X11: مدين | Y11: دائن | Z11: مدين | AA11: دائن | AB11: مدين | AC11: دائن | AD11: مدين | AE11: دائن | AF11: مدين | AG11: دائن | AH11: مدين | AI11: دائن | AJ11: مدين | AK11: دائن | AL11: مدين | AM11: دائن | AN11: مدين | AO11: دائن | AP11: مدين | AQ11: دائن
A12: 1 | G12: =IF(J12>K12,"متزن",IF(J12<K12,"غير متزن","")) | H12: =IF(J12>K12,"ذياده",IF(J12<K12,"ناقص","")) | I12: =IF(J12>K12,J12-K12,K12-J12) -> 0 | J12: =SUMIF($L$11:$AQ$11,$L$11,L12:AQ12) -> 0 | K12: =SUMIF($L$11:$AQ$11,$M$11,L12:AQ12) -> 0
A13: 2 | G13: =IF(J13>K13,"متزن",IF(J13<K13,"غير متزن","")) | H13: =IF(J13>K13,"ذياده",IF(J13<K13,"ناقص","")) | I13: =IF(J13>K13,J13-K13,K13-J13) -> 0 | J13: =SUMIF($L$11:$AQ$11,$L$11,L13:AQ13) -> 0 | K13: =SUMIF($L$11:$AQ$11,$M$11,L13:AQ13) -> 0
A14: 3 | G14: =IF(J14>K14,"متزن",IF(J14<K14,"غير متزن","")) | H14: =IF(J14>K14,"ذياده",IF(J14<K14,"ناقص","")) | I14: =IF(J14>K14,J14-K14,K14-J14) -> 0 | J14: =SUMIF($L$11:$AQ$11,$L$11,L14:AQ14) -> 0 | K14: =SUMIF($L$11:$AQ$11,$M$11,L14:AQ14) -> 0
A15: 4 | G15: =IF(J15>K15,"متزن",IF(J15<K15,"غير متزن","")) | H15: =IF(J15>K15,"ذياده",IF(J15<K15,"ناقص","")) | I15: =IF(J15>K15,J15-K15,K15-J15) -> 0 | J15: =SUMIF($L$11:$AQ$11,$L$11,L15:AQ15) -> 0 | K15: =SUMIF($L$11:$AQ$11,$M$11,L15:AQ15) -> 0
A16: 5 | G16: =IF(J16>K16,"متزن",IF(J16<K16,"غير متزن","")) | H16: =IF(J16>K16,"ذياده",IF(J16<K16,"ناقص","")) | I16: =IF(J16>K16,J16-K16,K16-J16) -> 0 | J16: =SUMIF($L$11:$AQ$11,$L$11,L16:AQ16) -> 0 | K16: =SUMIF($L$11:$AQ$11,$M$11,L16:AQ16) -> 0
A17: 6 | G17: =IF(J17>K17,"متزن",IF(J17<K17,"غير متزن","")) | H17: =IF(J17>K17,"ذياده",IF(J17<K17,"ناقص","")) | I17: =IF(J17>K17,J17-K17,K17-J17) -> 0 | J17: =SUMIF($L$11:$AQ$11,$L$11,L17:AQ17) -> 0 | K17: =SUMIF($L$11:$AQ$11,$M$11,L17:AQ17) -> 0
A18: 7 | G18: =IF(J18>K18,"متزن",IF(J18<K18,"غير متزن","")) | H18: =IF(J18>K18,"ذياده",IF(J18<K18,"ناقص","")) | I18: =IF(J18>K18,J18-K18,K18-J18) -> 0 | J18: =SUMIF($L$11:$AQ$11,$L$11,L18:AQ18) -> 0 | K18: =SUMIF($L$11:$AQ$11,$M$11,L18:AQ18) -> 0
A19: 8 | G19: =IF(J19>K19,"متزن",IF(J19<K19,"غير متزن","")) | H19: =IF(J19>K19,"ذياده",IF(J19<K19,"ناقص","")) | I19: =IF(J19>K19,J19-K19,K19-J19) -> 0 | J19: =SUMIF($L$11:$AQ$11,$L$11,L19:AQ19) -> 0 | K19: =SUMIF($L$11:$AQ$11,$M$11,L19:AQ19) -> 0
A20: 9 | G20: =IF(J20>K20,"متزن",IF(J20<K20,"غير متزن","")) | H20: =IF(J20>K20,"ذياده",IF(J20<K20,"ناقص","")) | I20: =IF(J20>K20,J20-K20,K20-J20) -> 0 | J20: =SUMIF($L$11:$AQ$11,$L$11,L20:AQ20) -> 0 | K20: =SUMIF($L$11:$AQ$11,$M$11,L20:AQ20) -> 0
A21: 10 | G21: =IF(J21>K21,"متزن",IF(J21<K21,"غير متزن","")) | H21: =IF(J21>K21,"ذياده",IF(J21<K21,"ناقص","")) | I21: =IF(J21>K21,J21-K21,K21-J21) -> 0 | J21: =SUMIF($L$11:$AQ$11,$L$11,L21:AQ21) -> 0 | K21: =SUMIF($L$11:$AQ$11,$M$11,L21:AQ21) -> 0
A22: 11 | G22: =IF(J22>K22,"متزن",IF(J22<K22,"غير متزن","")) | H22: =IF(J22>K22,"ذياده",IF(J22<K22,"ناقص","")) | I22: =IF(J22>K22,J22-K22,K22-J22) -> 0 | J22: =SUMIF($L$11:$AQ$11,$L$11,L22:AQ22) -> 0 | K22: =SUMIF($L$11:$AQ$11,$M$11,L22:AQ22) -> 0
A23: 12 | G23: =IF(J23>K23,"متزن",IF(J23<K23,"غير متزن","")) | H23: =IF(J23>K23,"ذياده",IF(J23<K23,"ناقص","")) | I23: =IF(J23>K23,J23-K23,K23-J23) -> 0 | J23: =SUMIF($L$11:$AQ$11,$L$11,L23:AQ23) -> 0 | K23: =SUMIF($L$11:$AQ$11,$M$11,L23:AQ23) -> 0
... A31: 20 | G31: =IF(J31>K31,"متزن",IF(J31<K31,"غير متزن","")) | H31: =IF(J31>K31,"ذياده",IF(J31<K31,"ناقص","")) | I31: =IF(J31>K31,J31-K31,K31-J31) -> 0 | J31: =SUMIF($L$11:$AQ$11,$L$11,L31:AQ31) -> 0 | K31: =SUMIF($L$11:$AQ$11,$M$11,L31:AQ31) -> 0
A32: الاجمالى | H32: =IF(J32>K32,"ذياده",IF(J32<K32,"ناقص","")) | J32: =SUM(J12:J31) -> 0 | K32: =SUM(K12:K31) -> 0 | L32: =SUM(L12:L31) -> 0 | M32: =SUM(M12:M31) -> 0 | N32: =SUM(N12:N31) -> 0 | O32: =SUM(O12:O31) -> 0 | P32: =SUM(P12:P31) -> 0 | Q32: =SUM(Q12:Q31) -> 0 | ... AQ32: =SUM(AQ12:AQ31) -> 0

Sheet 5
L8: =L32-M32+SUM('4'!L8:M8) -> 0 | N8: =N32-O32+SUM('4'!N8:O8) -> 0 | P8: =P32-Q32+SUM('4'!P8:Q8) -> 0 | R8: =R32-S32+SUM('4'!R8:S8) -> 0 | T8: =T32-U32+SUM('4'!T8:U8) -> 0 | V8: =V32-W32+SUM('4'!V8:W8) -> 0 | X8: =X32-Y32+SUM('4'!X8:Y8) -> 0 | Z8: =Z32-AA32+SUM('4'!Z8:AA8) -> 0 | AB8: =AB32-AC32+SUM('4'!AB8:AC8) -> 0 | AD8: =AD32-AE32+SUM('4'!AD8:AE8) -> 0 | AF8: =AF32-AG32+SUM('4'!AF8:AG8) -> 0 | AH8: =AH32-AI32+SUM('4'!AH8:AI8) -> 0 | AJ8: =AJ32-AK32+SUM('4'!AJ8:AK8) -> 0 | AL8: =AL32-AM32+SUM('4'!AL8:AM8) -> 0 | AN8: =AN32-AO32+SUM('4'!AN8:AO8) -> 0 | AP8: =AP32-AQ32+SUM('4'!AP8:AQ8) -> 0
A10: م | B10: التاريخ | C10: البيان | D10: نوع البيان | G10: متزن | H10: الفرق | J10: الاجمالى | L10: النقدية | N10: البنك | P10: المبيعات | R10: المشتريات | T10: العملاء | V10: الموردون | X10: جارى الشركات | Z10: رأس المال | AB10: المخزون | AD10: الايرادات | AF10: المصروفات | AH10: ارصده مدينة | AJ10: ارصده دائنة | AL10: ارصده دائنة | AN10: ارباح مرحله | AP10: القيمه المضافة
D11: صرف | E11: التحصيل | F11: اثبات | J11: مدين | K11: دائن | L11: مدين | M11: دائن | N11: مدين | O11: دائن | P11: مدين | Q11: دائن | R11: مدين | S11: دائن | T11: مدين | U11: دائن | V11: مدين | W11: دائن | X11: مدين | Y11: دائن | Z11: مدين | AA11: دائن | AB11: مدين | AC11: دائن | AD11: مدين | AE11: دائن | AF11: مدين | AG11: دائن | AH11: مدين | AI11: دائن | AJ11: مدين | AK11: دائن | AL11: مدين | AM11: دائن | AN11: مدين | AO11: دائن | AP11: مدين | AQ11: دائن
A12: 1 | G12: =IF(J12>K12,"متزن",IF(J12<K12,"غير متزن","")) | H12: =IF(J12>K12,"ذياده",IF(J12<K12,"ناقص","")) | I12: =IF(J12>K12,J12-K12,K12-J12) -> 0 | J12: =SUMIF($L$11:$AQ$11,$L$11,L12:AQ12) -> 0 | K12: =SUMIF($L$11:$AQ$11,$M$11,L12:AQ12) -> 0
A13: 2 | G13: =IF(J13>K13,"متزن",IF(J13<K13,"غير متزن","")) | H13: =IF(J13>K13,"ذياده",IF(J13<K13,"ناقص","")) | I13: =IF(J13>K13,J13-K13,K13-J13) -> 0 | J13: =SUMIF($L$11:$AQ$11,$L$11,L13:AQ13) -> 0 | K13: =SUMIF($L$11:$AQ$11,$M$11,L13:AQ13) -> 0
A14: 3 | G14: =IF(J14>K14,"متزن",IF(J14<K14,"غير متزن","")) | H14: =IF(J14>K14,"ذياده",IF(J14<K14,"ناقص","")) | I14: =IF(J14>K14,J14-K14,K14-J14) -> 0 | J14: =SUMIF($L$11:$AQ$11,$L$11,L14:AQ14) -> 0 | K14: =SUMIF($L$11:$AQ$11,$M$11,L14:AQ14) -> 0
A15: 4 | G15: =IF(J15>K15,"متزن",IF(J15<K15,"غير متزن","")) | H15: =IF(J15>K15,"ذياده",IF(J15<K15,"ناقص","")) | I15: =IF(J15>K15,J15-K15,K15-J15) -> 0 | J15: =SUMIF($L$11:$AQ$11,$L$11,L15:AQ15) -> 0 | K15: =SUMIF($L$11:$AQ$11,$M$11,L15:AQ15) -> 0
A16: 5 | G16: =IF(J16>K16,"متزن",IF(J16<K16,"غير متزن","")) | H16: =IF(J16>K16,"ذياده",IF(J16<K16,"ناقص","")) | I16: =IF(J16>K16,J16-K16,K16-J16) -> 0 | J16: =SUMIF($L$11:$AQ$11,$L$11,L16:AQ16) -> 0 | K16: =SUMIF($L$11:$AQ$11,$M$11,L16:AQ16) -> 0
A17: 6 | G17: =IF(J17>K17,"متزن",IF(J17<K17,"غير متزن","")) | H17: =IF(J17>K17,"ذياده",IF(J17<K17,"ناقص","")) | I17: =IF(J17>K17,J17-K17,K17-J17) -> 0 | J17: =SUMIF($L$11:$AQ$11,$L$11,L17:AQ17) -> 0 | K17: =SUMIF($L$11:$AQ$11,$M$11,L17:AQ17) -> 0
A18: 7 | G18: =IF(J18>K18,"متزن",IF(J18<K18,"غير متزن","")) | H18: =IF(J18>K18,"ذياده",IF(J18<K18,"ناقص","")) | I18: =IF(J18>K18,J18-K18,K18-J18) -> 0 | J18: =SUMIF($L$11:$AQ$11,$L$11,L18:AQ18) -> 0 | K18: =SUMIF($L$11:$AQ$11,$M$11,L18:AQ18) -> 0
A19: 8 | G19: =IF(J19>K19,"متزن",IF(J19<K19,"غير متزن","")) | H19: =IF(J19>K19,"ذياده",IF(J19<K19,"ناقص","")) | I19: =IF(J19>K19,J19-K19,K19-J19) -> 0 | J19: =SUMIF($L$11:$AQ$11,$L$11,L19:AQ19) -> 0 | K19: =SUMIF($L$11:$AQ$11,$M$11,L19:AQ19) -> 0
A20: 9 | G20: =IF(J20>K20,"متزن",IF(J20<K20,"غير متزن","")) | H20: =IF(J20>K20,"ذياده",IF(J20<K20,"ناقص","")) | I20: =IF(J20>K20,J20-K20,K20-J20) -> 0 | J20: =SUMIF($L$11:$AQ$11,$L$11,L20:AQ20) -> 0 | K20: =SUMIF($L$11:$AQ$11,$M$11,L20:AQ20) -> 0
A21: 10 | G21: =IF(J21>K21,"متزن",IF(J21<K21,"غير متزن","")) | H21: =IF(J21>K21,"ذياده",IF(J21<K21,"ناقص","")) | I21: =IF(J21>K21,J21-K21,K21-J21) -> 0 | J21: =SUMIF($L$11:$AQ$11,$L$11,L21:AQ21) -> 0 | K21: =SUMIF($L$11:$AQ$11,$M$11,L21:AQ21) -> 0
A22: 11 | G22: =IF(J22>K22,"متزن",IF(J22<K22,"غير متزن","")) | H22: =IF(J22>K22,"ذياده",IF(J22<K22,"ناقص","")) | I22: =IF(J22>K22,J22-K22,K22-J22) -> 0 | J22: =SUMIF($L$11:$AQ$11,$L$11,L22:AQ22) -> 0 | K22: =SUMIF($L$11:$AQ$11,$M$11,L22:AQ22) -> 0
A23: 12 | G23: =IF(J23>K23,"متزن",IF(J23<K23,"غير متزن","")) | H23: =IF(J23>K23,"ذياده",IF(J23<K23,"ناقص","")) | I23: =IF(J23>K23,J23-K23,K23-J23) -> 0 | J23: =SUMIF($L$11:$AQ$11,$L$11,L23:AQ23) -> 0 | K23: =SUMIF($L$11:$AQ$11,$M$11,L23:AQ23) -> 0
... A31: 20 | G31: =IF(J31>K31,"متزن",IF(J31<K31,"غير متزن","")) | H31: =IF(J31>K31,"ذياده",IF(J31<K31,"ناقص","")) | I31: =IF(J31>K31,J31-K31,K31-J31) -> 0 | J31: =SUMIF($L$11:$AQ$11,$L$11,L31:AQ31) -> 0 | K31: =SUMIF($L$11:$AQ$11,$M$11,L31:AQ31) -> 0
A32: الاجمالى | H32: =IF(J32>K32,"ذياده",IF(J32<K32,"ناقص","")) | J32: =SUM(J12:J31) -> 0 | K32: =SUM(K12:K31) -> 0 | L32: =SUM(L12:L31) -> 0 | M32: =SUM(M12:M31) -> 0 | N32: =SUM(N12:N31) -> 0 | O32: =SUM(O12:O31) -> 0 | P32: =SUM(P12:P31) -> 0 | Q32: =SUM(Q12:Q31) -> 0 | ... AQ32: =SUM(AQ12:AQ31) -> 0

Sheet 6
L8: =L32-M32+SUM('5'!L8:M8) -> 0 | N8: =N32-O32+SUM('5'!N8:O8) -> 0 | P8: =P32-Q32+SUM('5'!P8:Q8) -> 0 | R8: =R32-S32+SUM('5'!R8:S8) -> 0 | T8: =T32-U32+SUM('5'!T8:U8) -> 0 | V8: =V32-W32+SUM('5'!V8:W8) -> 0 | X8: =X32-Y32+SUM('5'!X8:Y8) -> 0 | Z8: =Z32-AA32+SUM('5'!Z8:AA8) -> 0 | AB8: =AB32-AC32+SUM('5'!AB8:AC8) -> 0 | AD8: =AD32-AE32+SUM('5'!AD8:AE8) -> 0 | AF8: =AF32-AG32+SUM('5'!AF8:AG8) -> 0 | AH8: =AH32-AI32+SUM('5'!AH8:AI8) -> 0 | AJ8: =AJ32-AK32+SUM('5'!AJ8:AK8) -> 0 | AL8: =AL32-AM32+SUM('5'!AL8:AM8) -> 0 | AN8: =AN32-AO32+SUM('5'!AN8:AO8) -> 0 | AP8: =AP32-AQ32+SUM('5'!AP8:AQ8) -> 0
A10: م | B10: التاريخ | C10: البيان | D10: نوع البيان | G10: متزن | H10: الفرق | J10: الاجمالى | L10: النقدية | N10: البنك | P10: المبيعات | R10: المشتريات | T10: العملاء | V10: الموردون | X10: جارى الشركات | Z10: رأس المال | AB10: المخزون | AD10: الايرادات | AF10: المصروفات | AH10: ارصده مدينة | AJ10: ارصده دائنة | AL10: ارصده دائنة | AN10: ارباح مرحله | AP10: القيمه المضافة
D11: صرف | E11: التحصيل | F11: اثبات | J11: مدين | K11: دائن | L11: مدين | M11: دائن | N11: مدين | O11: دائن | P11: مدين | Q11: دائن | R11: مدين | S11: دائن | T11: مدين | U11: دائن | V11: مدين | W11: دائن | X11: مدين | Y11: دائن | Z11: مدين | AA11: دائن | AB11: مدين | AC11: دائن | AD11: مدين | AE11: دائن | AF11: مدين | AG11: دائن | AH11: مدين | AI11: دائن | AJ11: مدين | AK11: دائن | AL11: مدين | AM11: دائن | AN11: مدين | AO11: دائن | AP11: مدين | AQ11: دائن
A12: 1 | G12: =IF(J12>K12,"متزن",IF(J12<K12,"غير متزن","")) | H12: =IF(J12>K12,"ذياده",IF(J12<K12,"ناقص","")) | I12: =IF(J12>K12,J12-K12,K12-J12) -> 0 | J12: =SUMIF($L$11:$AQ$11,$L$11,L12:AQ12) -> 0 | K12: =SUMIF($L$11:$AQ$11,$M$11,L12:AQ12) -> 0
A13: 2 | G13: =IF(J13>K13,"متزن",IF(J13<K13,"غير متزن","")) | H13: =IF(J13>K13,"ذياده",IF(J13<K13,"ناقص","")) | I13: =IF(J13>K13,J13-K13,K13-J13) -> 0 | J13: =SUMIF($L$11:$AQ$11,$L$11,L13:AQ13) -> 0 | K13: =SUMIF($L$11:$AQ$11,$M$11,L13:AQ13) -> 0
A14: 3 | G14: =IF(J14>K14,"متزن",IF(J14<K14,"غير متزن","")) | H14: =IF(J14>K14,"ذياده",IF(J14<K14,"ناقص","")) | I14: =IF(J14>K14,J14-K14,K14-J14) -> 0 | J14: =SUMIF($L$11:$AQ$11,$L$11,L14:AQ14) -> 0 | K14: =SUMIF($L$11:$AQ$11,$M$11,L14:AQ14) -> 0
A15: 4 | G15: =IF(J15>K15,"متزن",IF(J15<K15,"غير متزن","")) | H15: =IF(J15>K15,"ذياده",IF(J15<K15,"ناقص","")) | I15: =IF(J15>K15,J15-K15,K15-J15) -> 0 | J15: =SUMIF($L$11:$AQ$11,$L$11,L15:AQ15) -> 0 | K15: =SUMIF($L$11:$AQ$11,$M$11,L15:AQ15) -> 0
A16: 5 | G16: =IF(J16>K16,"متزن",IF(J16<K16,"غير متزن","")) | H16: =IF(J16>K16,"ذياده",IF(J16<K16,"ناقص","")) | I16: =IF(J16>K16,J16-K16,K16-J16) -> 0 | J16: =SUMIF($L$11:$AQ$11,$L$11,L16:AQ16) -> 0 | K16: =SUMIF($L$11:$AQ$11,$M$11,L16:AQ16) -> 0
A17: 6 | G17: =IF(J17>K17,"متزن",IF(J17<K17,"غير متزن","")) | H17: =IF(J17>K17,"ذياده",IF(J17<K17,"ناقص","")) | I17: =IF(J17>K17,J17-K17,K17-J17) -> 0 | J17: =SUMIF($L$11:$AQ$11,$L$11,L17:AQ17) -> 0 | K17: =SUMIF($L$11:$AQ$11,$M$11,L17:AQ17) -> 0
A18: 7 | G18: =IF(J18>K18,"متزن",IF(J18<K18,"غير متزن","")) | H18: =IF(J18>K18,"ذياده",IF(J18<K18,"ناقص","")) | I18: =IF(J18>K18,J18-K18,K18-J18) -> 0 | J18: =SUMIF($L$11:$AQ$11,$L$11,L18:AQ18) -> 0 | K18: =SUMIF($L$11:$AQ$11,$M$11,L18:AQ18) -> 0
A19: 8 | G19: =IF(J19>K19,"متزن",IF(J19<K19,"غير متزن","")) | H19: =IF(J19>K19,"ذياده",IF(J19<K19,"ناقص","")) | I19: =IF(J19>K19,J19-K19,K19-J19) -> 0 | J19: =SUMIF($L$11:$AQ$11,$L$11,L19:AQ19) -> 0 | K19: =SUMIF($L$11:$AQ$11,$M$11,L19:AQ19) -> 0
A20: 9 | G20: =IF(J20>K20,"متزن",IF(J20<K20,"غير متزن","")) | H20: =IF(J20>K20,"ذياده",IF(J20<K20,"ناقص","")) | I20: =IF(J20>K20,J20-K20,K20-J20) -> 0 | J20: =SUMIF($L$11:$AQ$11,$L$11,L20:AQ20) -> 0 | K20: =SUMIF($L$11:$AQ$11,$M$11,L20:AQ20) -> 0
A21: 10 | G21: =IF(J21>K21,"متزن",IF(J21<K21,"غير متزن","")) | H21: =IF(J21>K21,"ذياده",IF(J21<K21,"ناقص","")) | I21: =IF(J21>K21,J21-K21,K21-J21) -> 0 | J21: =SUMIF($L$11:$AQ$11,$L$11,L21:AQ21) -> 0 | K21: =SUMIF($L$11:$AQ$11,$M$11,L21:AQ21) -> 0
A22: 11 | G22: =IF(J22>K22,"متزن",IF(J22<K22,"غير متزن","")) | H22: =IF(J22>K22,"ذياده",IF(J22<K22,"ناقص","")) | I22: =IF(J22>K22,J22-K22,K22-J22) -> 0 | J22: =SUMIF($L$11:$AQ$11,$L$11,L22:AQ22) -> 0 | K22: =SUMIF($L$11:$AQ$11,$M$11,L22:AQ22) -> 0
A23: 12 | G23: =IF(J23>K23,"متزن",IF(J23<K23,"غير متزن","")) | H23: =IF(J23>K23,"ذياده",IF(J23<K23,"ناقص","")) | I23: =IF(J23>K23,J23-K23,K23-J23) -> 0 | J23: =SUMIF($L$11:$AQ$11,$L$11,L23:AQ23) -> 0 | K23: =SUMIF($L$11:$AQ$11,$M$11,L23:AQ23) -> 0
... A31: 20 | G31: =IF(J31>K31,"متزن",IF(J31<K31,"غير متزن","")) | H31: =IF(J31>K31,"ذياده",IF(J31<K31,"ناقص","")) | I31: =IF(J31>K31,J31-K31,K31-J31) -> 0 | J31: =SUMIF($L$11:$AQ$11,$L$11,L31:AQ31) -> 0 | K31: =SUMIF($L$11:$AQ$11,$M$11,L31:AQ31) -> 0
A32: الاجمالى | H32: =IF(J32>K32,"ذياده",IF(J32<K32,"ناقص","")) | J32: =SUM(J12:J31) -> 0 | K32: =SUM(K12:K31) -> 0 | L32: =SUM(L12:L31) -> 0 | M32: =SUM(M12:M31) -> 0 | N32: =SUM(N12:N31) -> 0 | O32: =SUM(O12:O31) -> 0 | P32: =SUM(P12:P31) -> 0 | Q32: =SUM(Q12:Q31) -> 0 | ... AQ32: =SUM(AQ12:AQ31) -> 0

Sheet 7
L8: =L32-M32+SUM('6'!L8:M8) -> -1000 | N8: =N32-O32+SUM('6'!N8:O8) -> 0 | P8: =P32-Q32+SUM('6'!P8:Q8) -> 0 | R8: =R32-S32+SUM('6'!R8:S8) -> 0 | T8: =T32-U32+SUM('6'!T8:U8) -> 0 | V8: =V32-W32+SUM('6'!V8:W8) -> 0 | X8: =X32-Y32+SUM('6'!X8:Y8) -> 0 | Z8: =Z32-AA32+SUM('6'!Z8:AA8) -> 0 | AB8: =AB32-AC32+SUM('6'!AB8:AC8) -> 0 | AD8: =AD32-AE32+SUM('6'!AD8:AE8) -> 0 | AF8: =AF32-AG32+SUM('6'!AF8:AG8) -> 0 | AH8: =AH32-AI32+SUM('6'!AH8:AI8) -> 0 | AJ8: =AJ32-AK32+SUM('6'!AJ8:AK8) -> 0 | AL8: =AL32-AM32+SUM('6'!AL8:AM8) -> 0 | AN8: =AN32-AO32+SUM('6'!AN8:AO8) -> 0 | AP8: =AP32-AQ32+SUM('6'!AP8:AQ8) -> 0
A10: م | B10: التاريخ | C10: البيان | D10: نوع البيان | G10: متزن | H10: الفرق | J10: الاجمالى | L10: النقدية | N10: البنك | P10: المبيعات | R10: المشتريات | T10: العملاء | V10: الموردون | X10: جارى الشركات | Z10: رأس المال | AB10: المخزون | AD10: الايرادات | AF10: المصروفات | AH10: ارصده مدينة | AJ10: ارصده دائنة | AL10: ارصده دائنة | AN10: ارباح مرحله | AP10: القيمه المضافة
D11: صرف | E11: التحصيل | F11: اثبات | J11: مدين | K11: دائن | L11: مدين | M11: دائن | N11: مدين | O11: دائن | P11: مدين | Q11: دائن | R11: مدين | S11: دائن | T11: مدين | U11: دائن | V11: مدين | W11: دائن | X11: مدين | Y11: دائن | Z11: مدين | AA11: دائن | AB11: مدين | AC11: دائن | AD11: مدين | AE11: دائن | AF11: مدين | AG11: دائن | AH11: مدين | AI11: دائن | AJ11: مدين | AK11: دائن | AL11: مدين | AM11: دائن | AN11: مدين | AO11: دائن | AP11: مدين | AQ11: دائن
A12: 1 | G12: =IF(J12>K12,"متزن",IF(J12<K12,"غير متزن","")) | H12: =IF(J12>K12,"ذياده",IF(J12<K12,"ناقص","")) | I12: =IF(J12>K12,J12-K12,K12-J12) -> 0 | J12: =SUMIF($L$11:$AQ$11,$L$11,L12:AQ12) -> 0 | K12: =SUMIF($L$11:$AQ$11,$M$11,L12:AQ12) -> 0
A13: 2 | G13: =IF(J13>K13,"متزن",IF(J13<K13,"غير متزن","")) | H13: =IF(J13>K13,"ذياده",IF(J13<K13,"ناقص","")) | I13: =IF(J13>K13,J13-K13,K13-J13) -> 0 | J13: =SUMIF($L$11:$AQ$11,$L$11,L13:AQ13) -> 0 | K13: =SUMIF($L$11:$AQ$11,$M$11,L13:AQ13) -> 0
A14: 3 | G14: =IF(J14>K14,"متزن",IF(J14<K14,"غير متزن","")) -> غير متزن | H14: =IF(J14>K14,"ذياده",IF(J14<K14,"ناقص","")) -> ناقص | I14: =IF(J14>K14,J14-K14,K14-J14) -> 1000 | J14: =SUMIF($L$11:$AQ$11,$L$11,L14:AQ14) -> 0 | K14: =SUMIF($L$11:$AQ$11,$M$11,L14:AQ14) -> 1000 | M14: 1000
A15: 4 | G15: =IF(J15>K15,"متزن",IF(J15<K15,"غير متزن","")) | H15: =IF(J15>K15,"ذياده",IF(J15<K15,"ناقص","")) | I15: =IF(J15>K15,J15-K15,K15-J15) -> 0 | J15: =SUMIF($L$11:$AQ$11,$L$11,L15:AQ15) -> 0 | K15: =SUMIF($L$11:$AQ$11,$M$11,L15:AQ15) -> 0
A16: 5 | G16: =IF(J16>K16,"متزن",IF(J16<K16,"غير متزن","")) | H16: =IF(J16>K16,"ذياده",IF(J16<K16,"ناقص","")) | I16: =IF(J16>K16,J16-K16,K16-J16) -> 0 | J16: =SUMIF($L$11:$AQ$11,$L$11,L16:AQ16) -> 0 | K16: =SUMIF($L$11:$AQ$11,$M$11,L16:AQ16) -> 0
A17: 6 | G17: =IF(J17>K17,"متزن",IF(J17<K17,"غير متزن","")) | H17: =IF(J17>K17,"ذياده",IF(J17<K17,"ناقص","")) | I17: =IF(J17>K17,J17-K17,K17-J17) -> 0 | J17: =SUMIF($L$11:$AQ$11,$L$11,L17:AQ17) -> 0 | K17: =SUMIF($L$11:$AQ$11,$M$11,L17:AQ17) -> 0
A18: 7 | G18: =IF(J18>K18,"متزن",IF(J18<K18,"غير متزن","")) | H18: =IF(J18>K18,"ذياده",IF(J18<K18,"ناقص","")) | I18: =IF(J18>K18,J18-K18,K18-J18) -> 0 | J18: =SUMIF($L$11:$AQ$11,$L$11,L18:AQ18) -> 0 | K18: =SUMIF($L$11:$AQ$11,$M$11,L18:AQ18) -> 0
A19: 8 | G19: =IF(J19>K19,"متزن",IF(J19<K19,"غير متزن","")) | H19: =IF(J19>K19,"ذياده",IF(J19<K19,"ناقص","")) | I19: =IF(J19>K19,J19-K19,K19-J19) -> 0 | J19: =SUMIF($L$11:$AQ$11,$L$11,L19:AQ19) -> 0 | K19: =SUMIF($L$11:$AQ$11,$M$11,L19:AQ19) -> 0
A20: 9 | G20: =IF(J20>K20,"متزن",IF(J20<K20,"غير متزن","")) | H20: =IF(J20>K20,"ذياده",IF(J20<K20,"ناقص","")) | I20: =IF(J20>K20,J20-K20,K20-J20) -> 0 | J20: =SUMIF($L$11:$AQ$11,$L$11,L20:AQ20) -> 0 | K20: =SUMIF($L$11:$AQ$11,$M$11,L20:AQ20) -> 0
A21: 10 | G21: =IF(J21>K21,"متزن",IF(J21<K21,"غير متزن","")) | H21: =IF(J21>K21,"ذياده",IF(J21<K21,"ناقص","")) | I21: =IF(J21>K21,J21-K21,K21-J21) -> 0 | J21: =SUMIF($L$11:$AQ$11,$L$11,L21:AQ21) -> 0 | K21: =SUMIF($L$11:$AQ$11,$M$11,L21:AQ21) -> 0
A22: 11 | G22: =IF(J22>K22,"متزن",IF(J22<K22,"غير متزن","")) | H22: =IF(J22>K22,"ذياده",IF(J22<K22,"ناقص","")) | I22: =IF(J22>K22,J22-K22,K22-J22) -> 0 | J22: =SUMIF($L$11:$AQ$11,$L$11,L22:AQ22) -> 0 | K22: =SUMIF($L$11:$AQ$11,$M$11,L22:AQ22) -> 0
A23: 12 | G23: =IF(J23>K23,"متزن",IF(J23<K23,"غير متزن","")) | H23: =IF(J23>K23,"ذياده",IF(J23<K23,"ناقص","")) | I23: =IF(J23>K23,J23-K23,K23-J23) -> 0 | J23: =SUMIF($L$11:$AQ$11,$L$11,L23:AQ23) -> 0 | K23: =SUMIF($L$11:$AQ$11,$M$11,L23:AQ23) -> 0
A24: 13 | G24: =IF(J24>K24,"متزن",IF(J24<K24,"غير متزن","")) | H24: =IF(J24>K24,"ذياده",IF(J24<K24,"ناقص","")) | I24: =IF(J24>K24,J24-K24,K24-J24) -> 0 | J24: =SUMIF($L$11:$AQ$11,$L$11,L24:AQ24) -> 0 | K24: =SUMIF($L$11:$AQ$11,$M$11,L24:AQ24) -> 0
A25: 14 | G25: =IF(J25>K25,"متزن",IF(J25<K25,"غير متزن","")) | H25: =IF(J25>K25,"ذياده",IF(J25<K25,"ناقص","")) | I25: =IF(J25>K25,J25-K25,K25-J25) -> 0 | J25: =SUMIF($L$11:$AQ$11,$L$11,L25:AQ25) -> 0 | K25: =SUMIF($L$11:$AQ$11,$M$11,L25:AQ25) -> 0
A26: 15 | G26: =IF(J26>K26,"متزن",IF(J26<K26,"غير متزن","")) | H26: =IF(J26>K26,"ذياده",IF(J26<K26,"ناقص","")) | I26: =IF(J26>K26,J26-K26,K26-J26) -> 0 | J26: =SUMIF($L$11:$AQ$11,$L$11,L26:AQ26) -> 0 | K26: =SUMIF($L$11:$AQ$11,$M$11,L26:AQ26) -> 0
... A31: 20 | G31: =IF(J31>K31,"متزن",IF(J31<K31,"غير متزن","")) | H31: =IF(J31>K31,"ذياده",IF(J31<K31,"ناقص","")) | I31: =IF(J31>K31,J31-K31,K31-J31) -> 0 | J31: =SUMIF($L$11:$AQ$11,$L$11,L31:AQ31) -> 0 | K31: =SUMIF($L$11:$AQ$11,$M$11,L31:AQ31) -> 0
A32: الاجمالى | H32: =IF(J32>K32,"ذياده",IF(J32<K32,"ناقص","")) -> ناقص | J32: =SUM(J12:J31) -> 0 | K32: =SUM(K12:K31) -> 1000 | L32: =SUM(L12:L31) -> 0 | M32: =SUM(M12:M31) -> 1000 | N32: =SUM(N12:N31) -> 0 | O32: =SUM(O12:O31) -> 0 | P32: =SUM(P12:P31) -> 0 | Q32: =SUM(Q12:Q31) -> 0 | ... AQ32: =SUM(AQ12:AQ31) -> 0

Sheet 8
L8: =L32-M32+SUM('7'!L8:M8) -> -1000 | N8: =N32-O32+SUM('7'!N8:O8) -> 0 | P8: =P32-Q32+SUM('7'!P8:Q8) -> 0 | R8: =R32-S32+SUM('7'!R8:S8) -> 0 | T8: =T32-U32+SUM('7'!T8:U8) -> 0 | V8: =V32-W32+SUM('7'!V8:W8) -> 0 | X8: =X32-Y32+SUM('7'!X8:Y8) -> 0 | Z8: =Z32-AA32+SUM('7'!Z8:AA8) -> 0 | AB8: =AB32-AC32+SUM('7'!AB8:AC8) -> 0 | AD8: =AD32-AE32+SUM('7'!AD8:AE8) -> 0 | AF8: =AF32-AG32+SUM('7'!AF8:AG8) -> 0 | AH8: =AH32-AI32+SUM('7'!AH8:AI8) -> 0 | AJ8: =AJ32-AK32+SUM('7'!AJ8:AK8) -> 0 | AL8: =AL32-AM32+SUM('7'!AL8:AM8) -> 0 | AN8: =AN32-AO32+SUM('7'!AN8:AO8) -> 0 | AP8: =AP32-AQ32+SUM('7'!AP8:AQ8) -> 0
A10: م | B10: التاريخ | C10: البيان | D10: نوع البيان | G10: متزن | H10: الفرق | J10: الاجمالى | L10: النقدية | N10: البنك | P10: المبيعات | R10: المشتريات | T10: العملاء | V10: الموردون | X10: جارى الشركات | Z10: رأس المال | AB10: المخزون | AD10: الايرادات | AF10: المصروفات | AH10: ارصده مدينة | AJ10: ارصده دائنة | AL10: ارصده دائنة | AN10: ارباح مرحله | AP10: القيمه المضافة
D11: صرف | E11: التحصيل | F11: اثبات | J11: مدين | K11: دائن | L11: مدين | M11: دائن | N11: مدين | O11: دائن | P11: مدين | Q11: دائن | R11: مدين | S11: دائن | T11: مدين | U11: دائن | V11: مدين | W11: دائن | X11: مدين | Y11: دائن | Z11: مدين | AA11: دائن | AB11: مدين | AC11: دائن | AD11: مدين | AE11: دائن | AF11: مدين | AG11: دائن | AH11: مدين | AI11: دائن | AJ11: مدين | AK11: دائن | AL11: مدين | AM11: دائن | AN11: مدين | AO11: دائن | AP11: مدين | AQ11: دائن
A12: 1 | G12: =IF(J12>K12,"متزن",IF(J12<K12,"غير متزن","")) | H12: =IF(J12>K12,"ذياده",IF(J12<K12,"ناقص","")) | I12: =IF(J12>K12,J12-K12,K12-J12) -> 0 | J12: =SUMIF($L$11:$AQ$11,$L$11,L12:AQ12) -> 0 | K12: =SUMIF($L$11:$AQ$11,$M$11,L12:AQ12) -> 0
A13: 2 | G13: =IF(J13>K13,"متزن",IF(J13<K13,"غير متزن","")) | H13: =IF(J13>K13,"ذياده",IF(J13<K13,"ناقص","")) | I13: =IF(J13>K13,J13-K13,K13-J13) -> 0 | J13: =SUMIF($L$11:$AQ$11,$L$11,L13:AQ13) -> 0 | K13: =SUMIF($L$11:$AQ$11,$M$11,L13:AQ13) -> 0
A14: 3 | G14: =IF(J14>K14,"متزن",IF(J14<K14,"غير متزن","")) | H14: =IF(J14>K14,"ذياده",IF(J14<K14,"ناقص","")) | I14: =IF(J14>K14,J14-K14,K14-J14) -> 0 | J14: =SUMIF($L$11:$AQ$11,$L$11,L14:AQ14) -> 0 | K14: =SUMIF($L$11:$AQ$11,$M$11,L14:AQ14) -> 0
A15: 4 | G15: =IF(J15>K15,"متزن",IF(J15<K15,"غير متزن","")) | H15: =IF(J15>K15,"ذياده",IF(J15<K15,"ناقص","")) | I15: =IF(J15>K15,J15-K15,K15-J15) -> 0 | J15: =SUMIF($L$11:$AQ$11,$L$11,L15:AQ15) -> 0 | K15: =SUMIF($L$11:$AQ$11,$M$11,L15:AQ15) -> 0
A16: 5 | G16: =IF(J16>K16,"متزن",IF(J16<K16,"غير متزن","")) | H16: =IF(J16>K16,"ذياده",IF(J16<K16,"ناقص","")) | I16: =IF(J16>K16,J16-K16,K16-J16) -> 0 | J16: =SUMIF($L$11:$AQ$11,$L$11,L16:AQ16) -> 0 | K16: =SUMIF($L$11:$AQ$11,$M$11,L16:AQ16) -> 0
A17: 6 | G17: =IF(J17>K17,"متزن",IF(J17<K17,"غير متزن","")) | H17: =IF(J17>K17,"ذياده",IF(J17<K17,"ناقص","")) | I17: =IF(J17>K17,J17-K17,K17-J17) -> 0 | J17: =SUMIF($L$11:$AQ$11,$L$11,L17:AQ17) -> 0 | K17: =SUMIF($L$11:$AQ$11,$M$11,L17:AQ17) -> 0
A18: 7 | G18: =IF(J18>K18,"متزن",IF(J18<K18,"غير متزن","")) | H18: =IF(J18>K18,"ذياده",IF(J18<K18,"ناقص","")) | I18: =IF(J18>K18,J18-K18,K18-J18) -> 0 | J18: =SUMIF($L$11:$AQ$11,$L$11,L18:AQ18) -> 0 | K18: =SUMIF($L$11:$AQ$11,$M$11,L18:AQ18) -> 0
A19: 8 | G19: =IF(J19>K19,"متزن",IF(J19<K19,"غير متزن","")) | H19: =IF(J19>K19,"ذياده",IF(J19<K19,"ناقص","")) | I19: =IF(J19>K19,J19-K19,K19-J19) -> 0 | J19: =SUMIF($L$11:$AQ$11,$L$11,L19:AQ19) -> 0 | K19: =SUMIF($L$11:$AQ$11,$M$11,L19:AQ19) -> 0
A20: 9 | G20: =IF(J20>K20,"متزن",IF(J20<K20,"غير متزن","")) | H20: =IF(J20>K20,"ذياده",IF(J20<K20,"ناقص","")) | I20: =IF(J20>K20,J20-K20,K20-J20) -> 0 | J20: =SUMIF($L$11:$AQ$11,$L$11,L20:AQ20) -> 0 | K20: =SUMIF($L$11:$AQ$11,$M$11,L20:AQ20) -> 0
A21: 10 | G21: =IF(J21>K21,"متزن",IF(J21<K21,"غير متزن","")) | H21: =IF(J21>K21,"ذياده",IF(J21<K21,"ناقص","")) | I21: =IF(J21>K21,J21-K21,K21-J21) -> 0 | J21: =SUMIF($L$11:$AQ$11,$L$11,L21:AQ21) -> 0 | K21: =SUMIF($L$11:$AQ$11,$M$11,L21:AQ21) -> 0
A22: 11 | G22: =IF(J22>K22,"متزن",IF(J22<K22,"غير متزن","")) | H22: =IF(J22>K22,"ذياده",IF(J22<K22,"ناقص","")) | I22: =IF(J22>K22,J22-K22,K22-J22) -> 0 | J22: =SUMIF($L$11:$AQ$11,$L$11,L22:AQ22) -> 0 | K22: =SUMIF($L$11:$AQ$11,$M$11,L22:AQ22) -> 0
A23: 12 | G23: =IF(J23>K23,"متزن",IF(J23<K23,"غير متزن","")) | H23: =IF(J23>K23,"ذياده",IF(J23<K23,"ناقص","")) | I23: =IF(J23>K23,J23-K23,K23-J23) -> 0 | J23: =SUMIF($L$11:$AQ$11,$L$11,L23:AQ23) -> 0 | K23: =SUMIF($L$11:$AQ$11,$M$11,L23:AQ23) -> 0
... A31: 20 | G31: =IF(J31>K31,"متزن",IF(J31<K31,"غير متزن","")) | H31: =IF(J31>K31,"ذياده",IF(J31<K31,"ناقص","")) | I31: =IF(J31>K31,J31-K31,K31-J31) -> 0 | J31: =SUMIF($L$11:$AQ$11,$L$11,L31:AQ31) -> 0 | K31: =SUMIF($L$11:$AQ$11,$M$11,L31:AQ31) -> 0
A32: الاجمالى | H32: =IF(J32>K32,"ذياده",IF(J32<K32,"ناقص","")) | J32: =SUM(J12:J31) -> 0 | K32: =SUM(K12:K31) -> 0 | L32: =SUM(L12:L31) -> 0 | M32: =SUM(M12:M31) -> 0 | N32: =SUM(N12:N31) -> 0 | O32: =SUM(O12:O31) -> 0 | P32: =SUM(P12:P31) -> 0 | Q32: =SUM(Q12:Q31) -> 0 | ... AQ32: =SUM(AQ12:AQ31) -> 0

Sheet 9
L8: =L32-M32+SUM('8'!L8:M8) -> -1000 | N8: =N32-O32+SUM('8'!N8:O8) -> 0 | P8: =P32-Q32+SUM('8'!P8:Q8) -> 0 | R8: =R32-S32+SUM('8'!R8:S8) -> 0 | T8: =T32-U32+SUM('8'!T8:U8) -> 0 | V8: =V32-W32+SUM('8'!V8:W8) -> 0 | X8: =X32-Y32+SUM('8'!X8:Y8) -> 0 | Z8: =Z32-AA32+SUM('8'!Z8:AA8) -> 0 | AB8: =AB32-AC32+SUM('8'!AB8:AC8) -> 0 | AD8: =AD32-AE32+SUM('8'!AD8:AE8) -> 0 | AF8: =AF32-AG32+SUM('8'!AF8:AG8) -> 0 | AH8: =AH32-AI32+SUM('8'!AH8:AI8) -> 0 | AJ8: =AJ32-AK32+SUM('8'!AJ8:AK8) -> 0 | AL8: =AL32-AM32+SUM('8'!AL8:AM8) -> 0 | AN8: =AN32-AO32+SUM('8'!AN8:AO8) -> 0 | AP8: =AP32-AQ32+SUM('8'!AP8:AQ8) -> 0
A10: م | B10: التاريخ | C10: البيان | D10: نوع البيان | G10: متزن | H10: الفرق | J10: الاجمالى | L10: النقدية | N10: البنك | P10: المبيعات | R10: المشتريات | T10: العملاء | V10: الموردون | X10: جارى الشركات | Z10: رأس المال | AB10: المخزون | AD10: الايرادات | AF10: المصروفات | AH10: ارصده مدينة | AJ10: ارصده دائنة | AL10: ارصده دائنة | AN10: ارباح مرحله | AP10: القيمه المضافة
D11: صرف | E11: التحصيل | F11: اثبات | J11: مدين | K11: دائن | L11: مدين | M11: دائن | N11: مدين | O11: دائن | P11: مدين | Q11: دائن | R11: مدين | S11: دائن | T11: مدين | U11: دائن | V11: مدين | W11: دائن | X11: مدين | Y11: دائن | Z11: مدين | AA11: دائن | AB11: مدين | AC11: دائن | AD11: مدين | AE11: دائن | AF11: مدين | AG11: دائن | AH11: مدين | AI11: دائن | AJ11: مدين | AK11: دائن | AL11: مدين | AM11: دائن | AN11: مدين | AO11: دائن | AP11: مدين | AQ11: دائن
A12: 1 | G12: =IF(J12>K12,"متزن",IF(J12<K12,"غير متزن","")) | H12: =IF(J12>K12,"ذياده",IF(J12<K12,"ناقص","")) | I12: =IF(J12>K12,J12-K12,K12-J12) -> 0 | J12: =SUMIF($L$11:$AQ$11,$L$11,L12:AQ12) -> 0 | K12: =SUMIF($L$11:$AQ$11,$M$11,L12:AQ12) -> 0
A13: 2 | G13: =IF(J13>K13,"متزن",IF(J13<K13,"غير متزن","")) | H13: =IF(J13>K13,"ذياده",IF(J13<K13,"ناقص","")) | I13: =IF(J13>K13,J13-K13,K13-J13) -> 0 | J13: =SUMIF($L$11:$AQ$11,$L$11,L13:AQ13) -> 0 | K13: =SUMIF($L$11:$AQ$11,$M$11,L13:AQ13) -> 0
A14: 3 | G14: =IF(J14>K14,"متزن",IF(J14<K14,"غير متزن","")) | H14: =IF(J14>K14,"ذياده",IF(J14<K14,"ناقص","")) | I14: =IF(J14>K14,J14-K14,K14-J14) -> 0 | J14: =SUMIF($L$11:$AQ$11,$L$11,L14:AQ14) -> 0 | K14: =SUMIF($L$11:$AQ$11,$M$11,L14:AQ14) -> 0
A15: 4 | G15: =IF(J15>K15,"متزن",IF(J15<K15,"غير متزن","")) | H15: =IF(J15>K15,"ذياده",IF(J15<K15,"ناقص","")) | I15: =IF(J15>K15,J15-K15,K15-J15) -> 0 | J15: =SUMIF($L$11:$AQ$11,$L$11,L15:AQ15) -> 0 | K15: =SUMIF($L$11:$AQ$11,$M$11,L15:AQ15) -> 0
A16: 5 | G16: =IF(J16>K16,"متزن",IF(J16<K16,"غير متزن","")) | H16: =IF(J16>K16,"ذياده",IF(J16<K16,"ناقص","")) | I16: =IF(J16>K16,J16-K16,K16-J16) -> 0 | J16: =SUMIF($L$11:$AQ$11,$L$11,L16:AQ16) -> 0 | K16: =SUMIF($L$11:$AQ$11,$M$11,L16:AQ16) -> 0
A17: 6 | G17: =IF(J17>K17,"متزن",IF(J17<K17,"غير متزن","")) | H17: =IF(J17>K17,"ذياده",IF(J17<K17,"ناقص","")) | I17: =IF(J17>K17,J17-K17,K17-J17) -> 0 | J17: =SUMIF($L$11:$AQ$11,$L$11,L17:AQ17) -> 0 | K17: =SUMIF($L$11:$AQ$11,$M$11,L17:AQ17) -> 0
A18: 7 | G18: =IF(J18>K18,"متزن",IF(J18<K18,"غير متزن","")) | H18: =IF(J18>K18,"ذياده",IF(J18<K18,"ناقص","")) | I18: =IF(J18>K18,J18-K18,K18-J18) -> 0 | J18: =SUMIF($L$11:$AQ$11,$L$11,L18:AQ18) -> 0 | K18: =SUMIF($L$11:$AQ$11,$M$11,L18:AQ18) -> 0
A19: 8 | G19: =IF(J19>K19,"متزن",IF(J19<K19,"غير متزن","")) | H19: =IF(J19>K19,"ذياده",IF(J19<K19,"ناقص","")) | I19: =IF(J19>K19,J19-K19,K19-J19) -> 0 | J19: =SUMIF($L$11:$AQ$11,$L$11,L19:AQ19) -> 0 | K19: =SUMIF($L$11:$AQ$11,$M$11,L19:AQ19) -> 0
A20: 9 | G20: =IF(J20>K20,"متزن",IF(J20<K20,"غير متزن","")) | H20: =IF(J20>K20,"ذياده",IF(J20<K20,"ناقص","")) | I20: =IF(J20>K20,J20-K20,K20-J20) -> 0 | J20: =SUMIF($L$11:$AQ$11,$L$11,L20:AQ20) -> 0 | K20: =SUMIF($L$11:$AQ$11,$M$11,L20:AQ20) -> 0
A21: 10 | G21: =IF(J21>K21,"متزن",IF(J21<K21,"غير متزن","")) | H21: =IF(J21>K21,"ذياده",IF(J21<K21,"ناقص","")) | I21: =IF(J21>K21,J21-K21,K21-J21) -> 0 | J21: =SUMIF($L$11:$AQ$11,$L$11,L21:AQ21) -> 0 | K21: =SUMIF($L$11:$AQ$11,$M$11,L21:AQ21) -> 0
A22: 11 | G22: =IF(J22>K22,"متزن",IF(J22<K22,"غير متزن","")) | H22: =IF(J22>K22,"ذياده",IF(J22<K22,"ناقص","")) | I22: =IF(J22>K22,J22-K22,K22-J22) -> 0 | J22: =SUMIF($L$11:$AQ$11,$L$11,L22:AQ22) -> 0 | K22: =SUMIF($L$11:$AQ$11,$M$11,L22:AQ22) -> 0
A23: 12 | G23: =IF(J23>K23,"متزن",IF(J23<K23,"غير متزن","")) | H23: =IF(J23>K23,"ذياده",IF(J23<K23,"ناقص","")) | I23: =IF(J23>K23,J23-K23,K23-J23) -> 0 | J23: =SUMIF($L$11:$AQ$11,$L$11,L23:AQ23) -> 0 | K23: =SUMIF($L$11:$AQ$11,$M$11,L23:AQ23) -> 0
... A31: 20 | G31: =IF(J31>K31,"متزن",IF(J31<K31,"غير متزن","")) | H31: =IF(J31>K31,"ذياده",IF(J31<K31,"ناقص","")) | I31: =IF(J31>K31,J31-K31,K31-J31) -> 0 | J31: =SUMIF($L$11:$AQ$11,$L$11,L31:AQ31) -> 0 | K31: =SUMIF($L$11:$AQ$11,$M$11,L31:AQ31) -> 0
A32: الاجمالى | H32: =IF(J32>K32,"ذياده",IF(J32<K32,"ناقص","")) | J32: =SUM(J12:J31) -> 0 | K32: =SUM(K12:K31) -> 0 | L32: =SUM(L12:L31) -> 0 | M32: =SUM(M12:M31) -> 0 | N32: =SUM(N12:N31) -> 0 | O32: =SUM(O12:O31) -> 0 | P32: =SUM(P12:P31) -> 0 | Q32: =SUM(Q12:Q31) -> 0 | ... AQ32: =SUM(AQ12:AQ31) -> 0

Sheet 10
L8: =L32-M32+SUM('9'!L8:M8) -> -1000 | N8: =N32-O32+SUM('9'!N8:O8) -> 0 | P8: =P32-Q32+SUM('9'!P8:Q8) -> 0 | R8: =R32-S32+SUM('9'!R8:S8) -> 0 | T8: =T32-U32+SUM('9'!T8:U8) -> 0 | V8: =V32-W32+SUM('9'!V8:W8) -> 0 | X8: =X32-Y32+SUM('9'!X8:Y8) -> 0 | Z8: =Z32-AA32+SUM('9'!Z8:AA8) -> 0 | AB8: =AB32-AC32+SUM('9'!AB8:AC8) -> 0 | AD8: =AD32-AE32+SUM('9'!AD8:AE8) -> 0 | AF8: =AF32-AG32+SUM('9'!AF8:AG8) -> 0 | AH8: =AH32-AI32+SUM('9'!AH8:AI8) -> 0 | AJ8: =AJ32-AK32+SUM('9'!AJ8:AK8) -> 0 | AL8: =AL32-AM32+SUM('9'!AL8:AM8) -> 0 | AN8: =AN32-AO32+SUM('9'!AN8:AO8) -> 0 | AP8: =AP32-AQ32+SUM('9'!AP8:AQ8) -> 0
A10: م | B10: التاريخ | C10: البيان | D10: نوع البيان | G10: متزن | H10: الفرق | J10: الاجمالى | L10: النقدية | N10: البنك | P10: المبيعات | R10: المشتريات | T10: العملاء | V10: الموردون | X10: جارى الشركات | Z10: رأس المال | AB10: المخزون | AD10: الايرادات | AF10: المصروفات | AH10: ارصده مدينة | AJ10: ارصده دائنة | AL10: ارصده دائنة | AN10: ارباح مرحله | AP10: القيمه المضافة
D11: صرف | E11: التحصيل | F11: اثبات | J11: مدين | K11: دائن | L11: مدين | M11: دائن | N11: مدين | O11: دائن | P11: مدين | Q11: دائن | R11: مدين | S11: دائن | T11: مدين | U11: دائن | V11: مدين | W11: دائن | X11: مدين | Y11: دائن | Z11: مدين | AA11: دائن | AB11: مدين | AC11: دائن | AD11: مدين | AE11: دائن | AF11: مدين | AG11: دائن | AH11: مدين | AI11: دائن | AJ11: مدين | AK11: دائن | AL11: مدين | AM11: دائن | AN11: مدين | AO11: دائن | AP11: مدين | AQ11: دائن
A12: 1 | G12: =IF(J12>K12,"متزن",IF(J12<K12,"غير متزن","")) | H12: =IF(J12>K12,"ذياده",IF(J12<K12,"ناقص","")) | I12: =IF(J12>K12,J12-K12,K12-J12) -> 0 | J12: =SUMIF($L$11:$AQ$11,$L$11,L12:AQ12) -> 0 | K12: =SUMIF($L$11:$AQ$11,$M$11,L12:AQ12) -> 0
A13: 2 | G13: =IF(J13>K13,"متزن",IF(J13<K13,"غير متزن","")) | H13: =IF(J13>K13,"ذياده",IF(J13<K13,"ناقص","")) | I13: =IF(J13>K13,J13-K13,K13-J13) -> 0 | J13: =SUMIF($L$11:$AQ$11,$L$11,L13:AQ13) -> 0 | K13: =SUMIF($L$11:$AQ$11,$M$11,L13:AQ13) -> 0
A14: 3 | G14: =IF(J14>K14,"متزن",IF(J14<K14,"غير متزن","")) | H14: =IF(J14>K14,"ذياده",IF(J14<K14,"ناقص","")) | I14: =IF(J14>K14,J14-K14,K14-J14) -> 0 | J14: =SUMIF($L$11:$AQ$11,$L$11,L14:AQ14) -> 0 | K14: =SUMIF($L$11:$AQ$11,$M$11,L14:AQ14) -> 0
A15: 4 | G15: =IF(J15>K15,"متزن",IF(J15<K15,"غير متزن","")) | H15: =IF(J15>K15,"ذياده",IF(J15<K15,"ناقص","")) | I15: =IF(J15>K15,J15-K15,K15-J15) -> 0 | J15: =SUMIF($L$11:$AQ$11,$L$11,L15:AQ15) -> 0 | K15: =SUMIF($L$11:$AQ$11,$M$11,L15:AQ15) -> 0
A16: 5 | G16: =IF(J16>K16,"متزن",IF(J16<K16,"غير متزن","")) | H16: =IF(J16>K16,"ذياده",IF(J16<K16,"ناقص","")) | I16: =IF(J16>K16,J16-K16,K16-J16) -> 0 | J16: =SUMIF($L$11:$AQ$11,$L$11,L16:AQ16) -> 0 | K16: =SUMIF($L$11:$AQ$11,$M$11,L16:AQ16) -> 0
A17: 6 | G17: =IF(J17>K17,"متزن",IF(J17<K17,"غير متزن","")) | H17: =IF(J17>K17,"ذياده",IF(J17<K17,"ناقص","")) | I17: =IF(J17>K17,J17-K17,K17-J17) -> 0 | J17: =SUMIF($L$11:$AQ$11,$L$11,L17:AQ17) -> 0 | K17: =SUMIF($L$11:$AQ$11,$M$11,L17:AQ17) -> 0
A18: 7 | G18: =IF(J18>K18,"متزن",IF(J18<K18,"غير متزن","")) | H18: =IF(J18>K18,"ذياده",IF(J18<K18,"ناقص","")) | I18: =IF(J18>K18,J18-K18,K18-J18) -> 0 | J18: =SUMIF($L$11:$AQ$11,$L$11,L18:AQ18) -> 0 | K18: =SUMIF($L$11:$AQ$11,$M$11,L18:AQ18) -> 0
A19: 8 | G19: =IF(J19>K19,"متزن",IF(J19<K19,"غير متزن","")) | H19: =IF(J19>K19,"ذياده",IF(J19<K19,"ناقص","")) | I19: =IF(J19>K19,J19-K19,K19-J19) -> 0 | J19: =SUMIF($L$11:$AQ$11,$L$11,L19:AQ19) -> 0 | K19: =SUMIF($L$11:$AQ$11,$M$11,L19:AQ19) -> 0
A20: 9 | G20: =IF(J20>K20,"متزن",IF(J20<K20,"غير متزن","")) | H20: =IF(J20>K20,"ذياده",IF(J20<K20,"ناقص","")) | I20: =IF(J20>K20,J20-K20,K20-J20) -> 0 | J20: =SUMIF($L$11:$AQ$11,$L$11,L20:AQ20) -> 0 | K20: =SUMIF($L$11:$AQ$11,$M$11,L20:AQ20) -> 0
A21: 10 | G21: =IF(J21>K21,"متزن",IF(J21<K21,"غير متزن","")) | H21: =IF(J21>K21,"ذياده",IF(J21<K21,"ناقص","")) | I21: =IF(J21>K21,J21-K21,K21-J21) -> 0 | J21: =SUMIF($L$11:$AQ$11,$L$11,L21:AQ21) -> 0 | K21: =SUMIF($L$11:$AQ$11,$M$11,L21:AQ21) -> 0
A22: 11 | G22: =IF(J22>K22,"متزن",IF(J22<K22,"غير متزن","")) | H22: =IF(J22>K22,"ذياده",IF(J22<K22,"ناقص","")) | I22: =IF(J22>K22,J22-K22,K22-J22) -> 0 | J22: =SUMIF($L$11:$AQ$11,$L$11,L22:AQ22) -> 0 | K22: =SUMIF($L$11:$AQ$11,$M$11,L22:AQ22) -> 0
A23: 12 | G23: =IF(J23>K23,"متزن",IF(J23<K23,"غير متزن","")) | H23: =IF(J23>K23,"ذياده",IF(J23<K23,"ناقص","")) | I23: =IF(J23>K23,J23-K23,K23-J23) -> 0 | J23: =SUMIF($L$11:$AQ$11,$L$11,L23:AQ23) -> 0 | K23: =SUMIF($L$11:$AQ$11,$M$11,L23:AQ23) -> 0
... A31: 20 | G31: =IF(J31>K31,"متزن",IF(J31<K31,"غير متزن","")) | H31: =IF(J31>K31,"ذياده",IF(J31<K31,"ناقص","")) | I31: =IF(J31>K31,J31-K31,K31-J31) -> 0 | J31: =SUMIF($L$11:$AQ$11,$L$11,L31:AQ31) -> 0 | K31: =SUMIF($L$11:$AQ$11,$M$11,L31:AQ31) -> 0
A32: الاجمالى | H32: =IF(J32>K32,"ذياده",IF(J32<K32,"ناقص","")) | J32: =SUM(J12:J31) -> 0 | K32: =SUM(K12:K31) -> 0 | L32: =SUM(L12:L31) -> 0 | M32: =SUM(M12:M31) -> 0 | N32: =SUM(N12:N31) -> 0 | O32: =SUM(O12:O31) -> 0 | P32: =SUM(P12:P31) -> 0 | Q32: =SUM(Q12:Q31) -> 0 | ... AQ32: =SUM(AQ12:AQ31) -> 0

Sheet 11
L8: =L32-M32+SUM('10'!L8:M8) -> -1000 | N8: =N32-O32+SUM('10'!N8:O8) -> 0 | P8: =P32-Q32+SUM('10'!P8:Q8) -> 0 | R8: =R32-S32+SUM('10'!R8:S8) -> 0 | T8: =T32-U32+SUM('10'!T8:U8) -> 0 | V8: =V32-W32+SUM('10'!V8:W8) -> 0 | X8: =X32-Y32+SUM('10'!X8:Y8) -> 0 | Z8: =Z32-AA32+SUM('10'!Z8:AA8) -> 0 | AB8: =AB32-AC32+SUM('10'!AB8:AC8) -> 0 | AD8: =AD32-AE32+SUM('10'!AD8:AE8) -> 0 | AF8: =AF32-AG32+SUM('10'!AF8:AG8) -> 0 | AH8: =AH32-AI32+SUM('10'!AH8:AI8) -> 0 | AJ8: =AJ32-AK32+SUM('10'!AJ8:AK8) -> 0 | AL8: =AL32-AM32+SUM('10'!AL8:AM8) -> 0 | AN8: =AN32-AO32+SUM('10'!AN8:AO8) -> 0 | AP8: =AP32-AQ32+SUM('10'!AP8:AQ8) -> 0
A10: م | B10: التاريخ | C10: البيان | D10: نوع البيان | G10: متزن | H10: الفرق | J10: الاجمالى | L10: النقدية | N10: البنك | P10: المبيعات | R10: المشتريات | T10: العملاء | V10: الموردون | X10: جارى الشركات | Z10: رأس المال | AB10: المخزون | AD10: الايرادات | AF10: المصروفات | AH10: ارصده مدينة | AJ10: ارصده دائنة | AL10: ارصده دائنة | AN10: ارباح مرحله | AP10: القيمه المضافة
D11: صرف | E11: التحصيل | F11: اثبات | J11: مدين | K11: دائن | L11: مدين | M11: دائن | N11: مدين | O11: دائن | P11: مدين | Q11: دائن | R11: مدين | S11: دائن | T11: مدين | U11: دائن | V11: مدين | W11: دائن | X11: مدين | Y11: دائن | Z11: مدين | AA11: دائن | AB11: مدين | AC11: دائن | AD11: مدين | AE11: دائن | AF11: مدين | AG11: دائن | AH11: مدين | AI11: دائن | AJ11: مدين | AK11: دائن | AL11: مدين | AM11: دائن | AN11: مدين | AO11: دائن | AP11: مدين | AQ11: دائن
A12: 1 | G12: =IF(J12>K12,"متزن",IF(J12<K12,"غير متزن","")) | H12: =IF(J12>K12,"ذياده",IF(J12<K12,"ناقص","")) | I12: =IF(J12>K12,J12-K12,K12-J12) -> 0 | J12: =SUMIF($L$11:$AQ$11,$L$11,L12:AQ12) -> 0 | K12: =SUMIF($L$11:$AQ$11,$M$11,L12:AQ12) -> 0
A13: 2 | G13: =IF(J13>K13,"متزن",IF(J13<K13,"غير متزن","")) | H13: =IF(J13>K13,"ذياده",IF(J13<K13,"ناقص","")) | I13: =IF(J13>K13,J13-K13,K13-J13) -> 0 | J13: =SUMIF($L$11:$AQ$11,$L$11,L13:AQ13) -> 0 | K13: =SUMIF($L$11:$AQ$11,$M$11,L13:AQ13) -> 0
A14: 3 | G14: =IF(J14>K14,"متزن",IF(J14<K14,"غير متزن","")) | H14: =IF(J14>K14,"ذياده",IF(J14<K14,"ناقص","")) | I14: =IF(J14>K14,J14-K14,K14-J14) -> 0 | J14: =SUMIF($L$11:$AQ$11,$L$11,L14:AQ14) -> 0 | K14: =SUMIF($L$11:$AQ$11,$M$11,L14:AQ14) -> 0
A15: 4 | G15: =IF(J15>K15,"متزن",IF(J15<K15,"غير متزن","")) | H15: =IF(J15>K15,"ذياده",IF(J15<K15,"ناقص","")) | I15: =IF(J15>K15,J15-K15,K15-J15) -> 0 | J15: =SUMIF($L$11:$AQ$11,$L$11,L15:AQ15) -> 0 | K15: =SUMIF($L$11:$AQ$11,$M$11,L15:AQ15) -> 0
A16: 5 | G16: =IF(J16>K16,"متزن",IF(J16<K16,"غير متزن","")) | H16: =IF(J16>K16,"ذياده",IF(J16<K16,"ناقص","")) | I16: =IF(J16>K16,J16-K16,K16-J16) -> 0 | J16: =SUMIF($L$11:$AQ$11,$L$11,L16:AQ16) -> 0 | K16: =SUMIF($L$11:$AQ$11,$M$11,L16:AQ16) -> 0
A17: 6 | G17: =IF(J17>K17,"متزن",IF(J17<K17,"غير متزن","")) | H17: =IF(J17>K17,"ذياده",IF(J17<K17,"ناقص","")) | I17: =IF(J17>K17,J17-K17,K17-J17) -> 0 | J17: =SUMIF($L$11:$AQ$11,$L$11,L17:AQ17) -> 0 | K17: =SUMIF($L$11:$AQ$11,$M$11,L17:AQ17) -> 0
A18: 7 | G18: =IF(J18>K18,"متزن",IF(J18<K18,"غير متزن","")) | H18: =IF(J18>K18,"ذياده",IF(J18<K18,"ناقص","")) | I18: =IF(J18>K18,J18-K18,K18-J18) -> 0 | J18: =SUMIF($L$11:$AQ$11,$L$11,L18:AQ18) -> 0 | K18: =SUMIF($L$11:$AQ$11,$M$11,L18:AQ18) -> 0
A19: 8 | G19: =IF(J19>K19,"متزن",IF(J19<K19,"غير متزن","")) | H19: =IF(J19>K19,"ذياده",IF(J19<K19,"ناقص","")) | I19: =IF(J19>K19,J19-K19,K19-J19) -> 0 | J19: =SUMIF($L$11:$AQ$11,$L$11,L19:AQ19) -> 0 | K19: =SUMIF($L$11:$AQ$11,$M$11,L19:AQ19) -> 0
A20: 9 | G20: =IF(J20>K20,"متزن",IF(J20<K20,"غير متزن","")) | H20: =IF(J20>K20,"ذياده",IF(J20<K20,"ناقص","")) | I20: =IF(J20>K20,J20-K20,K20-J20) -> 0 | J20: =SUMIF($L$11:$AQ$11,$L$11,L20:AQ20) -> 0 | K20: =SUMIF($L$11:$AQ$11,$M$11,L20:AQ20) -> 0
A21: 10 | G21: =IF(J21>K21,"متزن",IF(J21<K21,"غير متزن","")) | H21: =IF(J21>K21,"ذياده",IF(J21<K21,"ناقص","")) | I21: =IF(J21>K21,J21-K21,K21-J21) -> 0 | J21: =SUMIF($L$11:$AQ$11,$L$11,L21:AQ21) -> 0 | K21: =SUMIF($L$11:$AQ$11,$M$11,L21:AQ21) -> 0
A22: 11 | G22: =IF(J22>K22,"متزن",IF(J22<K22,"غير متزن","")) | H22: =IF(J22>K22,"ذياده",IF(J22<K22,"ناقص","")) | I22: =IF(J22>K22,J22-K22,K22-J22) -> 0 | J22: =SUMIF($L$11:$AQ$11,$L$11,L22:AQ22) -> 0 | K22: =SUMIF($L$11:$AQ$11,$M$11,L22:AQ22) -> 0
